Workbook
Name Slicer_time1: #REF!
Name Slicer_time: #REF!

Sheet Pivot
A1: =NOW() -> 46204.554

Sheet Now
A1: =NOW() -> 46204.554 | C1: 0.33333333 | D1: 0.35416667 | E1: 0.375 | F1: 0.39583333 | G1: 0.41666667 | H1: 0.4375 | I1: 0.45833333 | J1: 0.47916667 | K1: 0.5 | L1: 0.52083333 | M1: 0.54166667 | N1: 0.5625 | O1: 0.58333333 | P1: 0.60416667 | Q1: 0.625 | R1: 0.64583333 | S1: 0.66666667 | T1: 0.6875 | U1: 0.70833333 | V1: 0.72916667 | W1: 0.75 | X1: 0.77083333 | Y1: 0.79166667 | Z1: 0.8125 | AA1: 0.83333333 | AB1: 0.85416667 | AC1: 0.875 | AD1: 0.89583333 | AE1: 0.91666667 | AF1: 0.9375 | AG1: 0.95833333 | AH1: 0.97916667 | AI1: 1 | AJ1: 1.0208333 | AK1: 1.0416667 | AL1: 1.0625 | AM1: 1.0833333
A2: =MROUND(A1,"0:30") -> 46204.562
B3: {=INDEX(Schedule!$A:$AL,MATCH(ROUNDDOWN($A$2,0),Schedule!$A:$A,0),1)} -> #N/A | C3: {=INDEX(Schedule!$A:$AL,MATCH(ROUNDDOWN($A$2,0),Schedule!$A:$A,0),2)} -> #N/A | D3: {=INDEX(Schedule!$A:$AL,MATCH(ROUNDDOWN($A$2,0),Schedule!$A:$A,0),3)} -> #N/A | E3: {=INDEX(Schedule!$A:$AL,MATCH(ROUNDDOWN($A$2,0),Schedule!$A:$A,0),4)} -> #N/A | F3: {=INDEX(Schedule!$A:$AL,MATCH(ROUNDDOWN($A$2,0),Schedule!$A:$A,0),5)} -> #N/A | G3: {=INDEX(Schedule!$A:$AL,MATCH(ROUNDDOWN($A$2,0),Schedule!$A:$A,0),6)} -> #N/A | H3: {=INDEX(Schedule!$A:$AL,MATCH(ROUNDDOWN($A$2,0),Schedule!$A:$A,0),7)} -> #N/A | I3: {=INDEX(Schedule!$A:$AL,MATCH(ROUNDDOWN($A$2,0),Schedule!$A:$A,0),8)} -> #N/A | J3: {=INDEX(Schedule!$A:$AL,MATCH(ROUNDDOWN($A$2,0),Schedule!$A:$A,0),9)} -> #N/A | K3: {=INDEX(Schedule!$A:$AL,MATCH(ROUNDDOWN($A$2,0),Schedule!$A:$A,0),10)} -> #N/A | L3: {=INDEX(Schedule!$A:$AL,MATCH(ROUNDDOWN($A$2,0),Schedule!$A:$A,0),11)} -> #N/A | M3: {=INDEX(Schedule!$A:$AL,MATCH(ROUNDDOWN($A$2,0),Schedule!$A:$A,0),12)} -> #N/A | N3: {=INDEX(Schedule!$A:$AL,MATCH(ROUNDDOWN($A$2,0),Schedule!$A:$A,0),13)} -> #N/A | O3: {=INDEX(Schedule!$A:$AL,MATCH(ROUNDDOWN($A$2,0),Schedule!$A:$A,0),14)} -> #N/A | P3: {=INDEX(Schedule!$A:$AL,MATCH(ROUNDDOWN($A$2,0),Schedule!$A:$A,0),15)} -> #N/A | Q3: {=INDEX(Schedule!$A:$AL,MATCH(ROUNDDOWN($A$2,0),Schedule!$A:$A,0),16)} -> #N/A | R3: {=INDEX(Schedule!$A:$AL,MATCH(ROUNDDOWN($A$2,0),Schedule!$A:$A,0),17)} -> #N/A | S3: {=INDEX(Schedule!$A:$AL,MATCH(ROUNDDOWN($A$2,0),Schedule!$A:$A,0),18)} -> #N/A | T3: {=INDEX(Schedule!$A:$AL,MATCH(ROUNDDOWN($A$2,0),Schedule!$A:$A,0),19)} -> #N/A | U3: {=INDEX(Schedule!$A:$AL,MATCH(ROUNDDOWN($A$2,0),Schedule!$A:$A,0),20)} -> #N/A | V3: {=INDEX(Schedule!$A:$AL,MATCH(ROUNDDOWN($A$2,0),Schedule!$A:$A,0),21)} -> #N/A | W3: {=INDEX(Schedule!$A:$AL,MATCH(ROUNDDOWN($A$2,0),Schedule!$A:$A,0),22)} -> #N/A | X3: {=INDEX(Schedule!$A:$AL,MATCH(ROUNDDOWN($A$2,0),Schedule!$A:$A,0),23)} -> #N/A | Y3: {=INDEX(Schedule!$A:$AL,MATCH(ROUNDDOWN($A$2,0),Schedule!$A:$A,0),24)} -> #N/A | Z3: {=INDEX(Schedule!$A:$AL,MATCH(ROUNDDOWN($A$2,0),Schedule!$A:$A,0),25)} -> #N/A | AA3: {=INDEX(Schedule!$A:$AL,MATCH(ROUNDDOWN($A$2,0),Schedule!$A:$A,0),26)} -> #N/A | AB3: {=INDEX(Schedule!$A:$AL,MATCH(ROUNDDOWN($A$2,0),Schedule!$A:$A,0),27)} -> #N/A | AC3: {=INDEX(Schedule!$A:$AL,MATCH(ROUNDDOWN($A$2,0),Schedule!$A:$A,0),28)} -> #N/A | AD3: {=INDEX(Schedule!$A:$AL,MATCH(ROUNDDOWN($A$2,0),Schedule!$A:$A,0),29)} -> #N/A | AE3: {=INDEX(Schedule!$A:$AL,MATCH(ROUNDDOWN($A$2,0),Schedule!$A:$A,0),30)} -> #N/A | AF3: {=INDEX(Schedule!$A:$AL,MATCH(ROUNDDOWN($A$2,0),Schedule!$A:$A,0),31)} -> #N/A | AG3: {=INDEX(Schedule!$A:$AL,MATCH(ROUNDDOWN($A$2,0),Schedule!$A:$A,0),32)} -> #N/A | AH3: {=INDEX(Schedule!$A:$AL,MATCH(ROUNDDOWN($A$2,0),Schedule!$A:$A,0),33)} -> #N/A | AI3: {=INDEX(Schedule!$A:$AL,MATCH(ROUNDDOWN($A$2,0),Schedule!$A:$A,0),34)} -> #N/A | AJ3: {=INDEX(Schedule!$A:$AL,MATCH(ROUNDDOWN($A$2,0),Schedule!$A:$A,0),35)} -> #N/A | AK3: {=INDEX(Schedule!$A:$AL,MATCH(ROUNDDOWN($A$2,0),Schedule!$A:$A,0),36)} -> #N/A | AL3: {=INDEX(Schedule!$A:$AL,MATCH(ROUNDDOWN($A$2,0),Schedule!$A:$A,0),37)} -> #N/A | AM3: {=INDEX(Schedule!$A:$AL,MATCH(ROUNDDOWN($A$2,0),Schedule!$A:$A,0),38)} -> #N/A
C6: time | D6: task
C7: =C1 -> 0.33333333 | D7: =C3 -> #N/A
C8: =D1 -> 0.35416667 | D8: =D3 -> #N/A
C9: =E1 -> 0.375 | D9: =E3 -> #N/A
C10: =F1 -> 0.39583333 | D10: =F3 -> #N/A
C11: =G1 -> 0.41666667 | D11: =G3 -> #N/A
C12: =H1 -> 0.4375 | D12: =H3 -> #N/A
C13: =I1 -> 0.45833333 | D13: =I3 -> #N/A
C14: =J1 -> 0.47916667 | D14: =J3 -> #N/A
C15: =K1 -> 0.5 | D15: =K3 -> #N/A
C16: =L1 -> 0.52083333 | D16: =L3 -> #N/A
C17: =M1 -> 0.54166667 | D17: =M3 -> #N/A
C18: =N1 -> 0.5625 | D18: =N3 -> #N/A
C19: =O1 -> 0.58333333 | D19: =O3 -> #N/A
C20: =P1 -> 0.60416667 | D20: =P3 -> #N/A
C21: =Q1 -> 0.625 | D21: =Q3 -> #N/A
C22: =R1 -> 0.64583333 | D22: =R3 -> #N/A
C23: =S1 -> 0.66666667 | D23: =S3 -> #N/A
C24: =T1 -> 0.6875 | D24: =T3 -> #N/A
C25: =U1 -> 0.70833333 | D25: =U3 -> #N/A
C26: =V1 -> 0.72916667 | D26: =V3 -> #N/A
C27: =W1 -> 0.75 | D27: =W3 -> #N/A
C28: =X1 -> 0.77083333 | D28: =X3 -> #N/A
C29: =Y1 -> 0.79166667 | D29: =Y3 -> #N/A
C30: =Z1 -> 0.8125 | D30: =Z3 -> #N/A
C31: =AA1 -> 0.83333333 | D31: =AA3 -> #N/A
C32: =AB1 -> 0.85416667 | D32: =AB3 -> #N/A
C33: =AC1 -> 0.875 | D33: =AC3 -> #N/A
C34: =AD1 -> 0.89583333 | D34: =AD3 -> #N/A
C35: =AE1 -> 0.91666667 | D35: =AE3 -> #N/A
C36: =AF1 -> 0.9375 | D36: =AF3 -> #N/A
C37: =AG1 -> 0.95833333 | D37: =AF3 -> #N/A
C38: =AH1 -> 0.97916667 | D38: =AH3 -> #N/A
C39: =AI1 -> 1 | D39: =AI3 -> #N/A
C40: =AJ1 -> 1.0208333 | D40: =AJ3 -> #N/A
C41: =AK1 -> 1.0416667 | D41: =AK3 -> #N/A
C42: =AL1 -> 1.0625 | D42: =AL3 -> #N/A
...

Sheet Planner
A1: =NOW() -> 46204.554 | B1: 0.33333333 | C1: 0.35416667 | D1: 0.375 | E1: 0.39583333 | F1: 0.41666667 | G1: 0.4375 | H1: 0.45833333 | I1: 0.47916667 | J1: 0.5 | K1: 0.52083333 | L1: 0.54166667 | M1: 0.5625 | N1: 0.58333333 | O1: 0.60416667 | P1: 0.625 | Q1: 0.64583333 | R1: 0.66666667 | S1: 0.6875 | T1: 0.70833333 | U1: 0.72916667 | V1: 0.75 | W1: 0.77083333 | X1: 0.79166667 | Y1: 0.8125 | Z1: 0.83333333 | AA1: 0.85416667 | AB1: 0.875 | AC1: 0.89583333 | AD1: 0.91666667 | AE1: 0.9375 | AF1: 0.95833333 | AG1: 0.97916667 | AH1: 1 | AI1: 1.0208333 | AJ1: 1.0416667 | AK1: 1.0625 | AL1: 1.0833333
A2: =MROUND(A1,"0:30") -> 46204.562 | D2: *Enter subjects of interest in Cell A5 and after
A3: {=INDEX('Static '!$A:$AL,MATCH(ROUNDDOWN($A$2,0),'Static '!$A:$A,0),1)} -> #N/A | B3: {=IF(INDEX('Static '!$A:$AL,MATCH(ROUNDDOWN($A$2,0),'Static '!$A:$A,0),2)=0,"",(INDEX('Static '!$A:$AL,MATCH(ROUNDDOWN($A$2,0),'Static '!$A:$A,0),2)))} -> #N/A | C3: {=IF(INDEX('Static '!$A:$AL,MATCH(ROUNDDOWN($A$2,0),'Static '!$A:$A,0),3)=0,"",(INDEX('Static '!$A:$AL,MATCH(ROUNDDOWN($A$2,0),'Static '!$A:$A,0),3)))} -> #N/A | D3: {=IF(INDEX('Static '!$A:$AL,MATCH(ROUNDDOWN($A$2,0),'Static '!$A:$A,0),4)=0,"",(INDEX('Static '!$A:$AL,MATCH(ROUNDDOWN($A$2,0),'Static '!$A:$A,0),4)))} -> #N/A | E3: {=IF(INDEX('Static '!$A:$AL,MATCH(ROUNDDOWN($A$2,0),'Static '!$A:$A,0),5)=0,"",(INDEX('Static '!$A:$AL,MATCH(ROUNDDOWN($A$2,0),'Static '!$A:$A,0),5)))} -> #N/A | F3: {=IF(INDEX('Static '!$A:$AL,MATCH(ROUNDDOWN($A$2,0),'Static '!$A:$A,0),6)=0,"",(INDEX('Static '!$A:$AL,MATCH(ROUNDDOWN($A$2,0),'Static '!$A:$A,0),6)))} -> #N/A | G3: {=IF(INDEX('Static '!$A:$AL,MATCH(ROUNDDOWN($A$2,0),'Static '!$A:$A,0),7)=0,"",(INDEX('Static '!$A:$AL,MATCH(ROUNDDOWN($A$2,0),'Static '!$A:$A,0),7)))} -> #N/A | H3: {=IF(INDEX('Static '!$A:$AL,MATCH(ROUNDDOWN($A$2,0),'Static '!$A:$A,0),8)=0,"",(INDEX('Static '!$A:$AL,MATCH(ROUNDDOWN($A$2,0),'Static '!$A:$A,0),8)))} -> #N/A | I3: {=IF(INDEX('Static '!$A:$AL,MATCH(ROUNDDOWN($A$2,0),'Static '!$A:$A,0),9)=0,"",(INDEX('Static '!$A:$AL,MATCH(ROUNDDOWN($A$2,0),'Static '!$A:$A,0),9)))} -> #N/A | J3: {=IF(INDEX('Static '!$A:$AL,MATCH(ROUNDDOWN($A$2,0),'Static '!$A:$A,0),10)=0,"",(INDEX('Static '!$A:$AL,MATCH(ROUNDDOWN($A$2,0),'Static '!$A:$A,0),10)))} -> #N/A | K3: {=IF(INDEX('Static '!$A:$AL,MATCH(ROUNDDOWN($A$2,0),'Static '!$A:$A,0),11)=0,"",(INDEX('Static '!$A:$AL,MATCH(ROUNDDOWN($A$2,0),'Static '!$A:$A,0),11)))} -> #N/A | L3: {=IF(INDEX('Static '!$A:$AL,MATCH(ROUNDDOWN($A$2,0),'Static '!$A:$A,0),12)=0,"",(INDEX('Static '!$A:$AL,MATCH(ROUNDDOWN($A$2,0),'Static '!$A:$A,0),12)))} -> #N/A | M3: {=IF(INDEX('Static '!$A:$AL,MATCH(ROUNDDOWN($A$2,0),'Static '!$A:$A,0),13)=0,"",(INDEX('Static '!$A:$AL,MATCH(ROUNDDOWN($A$2,0),'Static '!$A:$A,0),13)))} -> #N/A | N3: {=IF(INDEX('Static '!$A:$AL,MATCH(ROUNDDOWN($A$2,0),'Static '!$A:$A,0),14)=0,"",(INDEX('Static '!$A:$AL,MATCH(ROUNDDOWN($A$2,0),'Static '!$A:$A,0),14)))} -> #N/A | O3: {=IF(INDEX('Static '!$A:$AL,MATCH(ROUNDDOWN($A$2,0),'Static '!$A:$A,0),15)=0,"",(INDEX('Static '!$A:$AL,MATCH(ROUNDDOWN($A$2,0),'Static '!$A:$A,0),15)))} -> #N/A | P3: {=IF(INDEX('Static '!$A:$AL,MATCH(ROUNDDOWN($A$2,0),'Static '!$A:$A,0),16)=0,"",(INDEX('Static '!$A:$AL,MATCH(ROUNDDOWN($A$2,0),'Static '!$A:$A,0),16)))} -> #N/A | Q3: {=IF(INDEX('Static '!$A:$AL,MATCH(ROUNDDOWN($A$2,0),'Static '!$A:$A,0),17)=0,"",(INDEX('Static '!$A:$AL,MATCH(ROUNDDOWN($A$2,0),'Static '!$A:$A,0),17)))} -> #N/A | R3: {=IF(INDEX('Static '!$A:$AL,MATCH(ROUNDDOWN($A$2,0),'Static '!$A:$A,0),18)=0,"",(INDEX('Static '!$A:$AL,MATCH(ROUNDDOWN($A$2,0),'Static '!$A:$A,0),18)))} -> #N/A | S3: {=IF(INDEX('Static '!$A:$AL,MATCH(ROUNDDOWN($A$2,0),'Static '!$A:$A,0),19)=0,"",(INDEX('Static '!$A:$AL,MATCH(ROUNDDOWN($A$2,0),'Static '!$A:$A,0),19)))} -> #N/A | T3: {=IF(INDEX('Static '!$A:$AL,MATCH(ROUNDDOWN($A$2,0),'Static '!$A:$A,0),20)=0,"",(INDEX('Static '!$A:$AL,MATCH(ROUNDDOWN($A$2,0),'Static '!$A:$A,0),20)))} -> #N/A | U3: {=IF(INDEX('Static '!$A:$AL,MATCH(ROUNDDOWN($A$2,0),'Static '!$A:$A,0),21)=0,"",(INDEX('Static '!$A:$AL,MATCH(ROUNDDOWN($A$2,0),'Static '!$A:$A,0),21)))} -> #N/A | V3: {=IF(INDEX('Static '!$A:$AL,MATCH(ROUNDDOWN($A$2,0),'Static '!$A:$A,0),22)=0,"",(INDEX('Static '!$A:$AL,MATCH(ROUNDDOWN($A$2,0),'Static '!$A:$A,0),22)))} -> #N/A | W3: {=IF(INDEX('Static '!$A:$AL,MATCH(ROUNDDOWN($A$2,0),'Static '!$A:$A,0),23)=0,"",(INDEX('Static '!$A:$AL,MATCH(ROUNDDOWN($A$2,0),'Static '!$A:$A,0),23)))} -> #N/A | X3: {=IF(INDEX('Static '!$A:$AL,MATCH(ROUNDDOWN($A$2,0),'Static '!$A:$A,0),24)=0,"",(INDEX('Static '!$A:$AL,MATCH(ROUNDDOWN($A$2,0),'Static '!$A:$A,0),24)))} -> #N/A | Y3: {=IF(INDEX('Static '!$A:$AL,MATCH(ROUNDDOWN($A$2,0),'Static '!$A:$A,0),25)=0,"",(INDEX('Static '!$A:$AL,MATCH(ROUNDDOWN($A$2,0),'Static '!$A:$A,0),25)))} -> #N/A | Z3: {=IF(INDEX('Static '!$A:$AL,MATCH(ROUNDDOWN($A$2,0),'Static '!$A:$A,0),26)=0,"",(INDEX('Static '!$A:$AL,MATCH(ROUNDDOWN($A$2,0),'Static '!$A:$A,0),26)))} -> #N/A | AA3: {=IF(INDEX('Static '!$A:$AL,MATCH(ROUNDDOWN($A$2,0),'Static '!$A:$A,0),27)=0,"",(INDEX('Static '!$A:$AL,MATCH(ROUNDDOWN($A$2,0),'Static '!$A:$A,0),27)))} -> #N/A | AB3: {=IF(INDEX('Static '!$A:$AL,MATCH(ROUNDDOWN($A$2,0),'Static '!$A:$A,0),28)=0,"",(INDEX('Static '!$A:$AL,MATCH(ROUNDDOWN($A$2,0),'Static '!$A:$A,0),28)))} -> #N/A | AC3: {=IF(INDEX('Static '!$A:$AL,MATCH(ROUNDDOWN($A$2,0),'Static '!$A:$A,0),29)=0,"",(INDEX('Static '!$A:$AL,MATCH(ROUNDDOWN($A$2,0),'Static '!$A:$A,0),29)))} -> #N/A | AD3: {=IF(INDEX('Static '!$A:$AL,MATCH(ROUNDDOWN($A$2,0),'Static '!$A:$A,0),30)=0,"",(INDEX('Static '!$A:$AL,MATCH(ROUNDDOWN($A$2,0),'Static '!$A:$A,0),30)))} -> #N/A | AE3: {=IF(INDEX('Static '!$A:$AL,MATCH(ROUNDDOWN($A$2,0),'Static '!$A:$A,0),31)=0,"",(INDEX('Static '!$A:$AL,MATCH(ROUNDDOWN($A$2,0),'Static '!$A:$A,0),31)))} -> #N/A | AF3: {=IF(INDEX('Static '!$A:$AL,MATCH(ROUNDDOWN($A$2,0),'Static '!$A:$A,0),32)=0,"",(INDEX('Static '!$A:$AL,MATCH(ROUNDDOWN($A$2,0),'Static '!$A:$A,0),32)))} -> #N/A | AG3: {=IF(INDEX('Static '!$A:$AL,MATCH(ROUNDDOWN($A$2,0),'Static '!$A:$A,0),33)=0,"",(INDEX('Static '!$A:$AL,MATCH(ROUNDDOWN($A$2,0),'Static '!$A:$A,0),33)))} -> #N/A | AH3: {=IF(INDEX('Static '!$A:$AL,MATCH(ROUNDDOWN($A$2,0),'Static '!$A:$A,0),34)=0,"",(INDEX('Static '!$A:$AL,MATCH(ROUNDDOWN($A$2,0),'Static '!$A:$A,0),34)))} -> #N/A | AI3: {=IF(INDEX('Static '!$A:$AL,MATCH(ROUNDDOWN($A$2,0),'Static '!$A:$A,0),35)=0,"",(INDEX('Static '!$A:$AL,MATCH(ROUNDDOWN($A$2,0),'Static '!$A:$A,0),35)))} -> #N/A | AJ3: {=IF(INDEX('Static '!$A:$AL,MATCH(ROUNDDOWN($A$2,0),'Static '!$A:$A,0),36)=0,"",(INDEX('Static '!$A:$AL,MATCH(ROUNDDOWN($A$2,0),'Static '!$A:$A,0),36)))} -> #N/A | AK3: {=IF(INDEX('Static '!$A:$AL,MATCH(ROUNDDOWN($A$2,0),'Static '!$A:$A,0),37)=0,"",(INDEX('Static '!$A:$AL,MATCH(ROUNDDOWN($A$2,0),'Static '!$A:$A,0),37)))} -> #N/A | AL3: {=IF(INDEX('Static '!$A:$AL,MATCH(ROUNDDOWN($A$2,0),'Static '!$A:$A,0),38)=0,"",(INDEX('Static '!$A:$AL,MATCH(ROUNDDOWN($A$2,0),'Static '!$A:$A,0),38)))} -> #N/A
B4: Time | C4: Static Task | D4: notes | E4: Time | F4: Adjusted Task
B5: =B1 -> 0.33333333 | C5: =B3 -> #N/A | D5: {=ifna(IF(INDEX(Subject!B:D,MATCH(F5,Subject!C:C,0),3)=0,"",(INDEX(Subject!B:D,MATCH(F5,Subject!C:C,0),3))),"")} | E5: =Now!C7 -> 0.33333333 | F5: =ifna(Now!D7,"") | G5: {=IF($F5="","",HYPERLINK(INDEX(Subject!$B:$E,MATCH($F5,Subject!C:C,0),4)))} | H5: {=IF($F5="","",HYPERLINK(INDEX(Subject!$B:$I,MATCH($F5,Subject!$C:$C,0),5)))} | I5: {=IF($F5="","",HYPERLINK(INDEX(Subject!$B:$I,MATCH($F5,Subject!$C:$C,0),6)))} | J5: {=IF($F5="","",HYPERLINK(INDEX(Subject!$B:$I,MATCH($F5,Subject!$C:$C,0),7)))} | K5: {=IF($F5="","",HYPERLINK(INDEX(Subject!$B:$I,MATCH($F5,Subject!$C:$C,0),8)))}
B6: =C1 -> 0.35416667 | C6: =C3 -> #N/A | D6: {=ifna(IF(INDEX(Subject!B:D,MATCH(F6,Subject!C:C,0),3)=0,"",(INDEX(Subject!B:D,MATCH(F6,Subject!C:C,0),3))),"")} | E6: =Now!C8 -> 0.35416667 | F6: =ifna(Now!D8,"") | G6: {=IF(F6="","",HYPERLINK(INDEX(Subject!B:E,MATCH(F6,Subject!C:C,0),4)))} | H6: {=IF($F6="","",HYPERLINK(INDEX(Subject!$B:$I,MATCH($F6,Subject!$C:$C,0),5)))} | I6: {=IF($F6="","",HYPERLINK(INDEX(Subject!$B:$I,MATCH($F6,Subject!$C:$C,0),6)))} | J6: {=IF($F6="","",HYPERLINK(INDEX(Subject!$B:$I,MATCH($F6,Subject!$C:$C,0),7)))} | K6: {=IF($F6="","",HYPERLINK(INDEX(Subject!$B:$I,MATCH($F6,Subject!$C:$C,0),8)))}
B7: =D1 -> 0.375 | C7: =D3 -> #N/A | D7: {=ifna(IF(INDEX(Subject!B:D,MATCH(F7,Subject!C:C,0),3)=0,"",(INDEX(Subject!B:D,MATCH(F7,Subject!C:C,0),3))),"")} | E7: =Now!C9 -> 0.375 | F7: =ifna(Now!D9,"") | G7: {=IF(F7="","",HYPERLINK(INDEX(Subject!B:E,MATCH(F7,Subject!C:C,0),4)))} | H7: {=IF($F7="","",HYPERLINK(INDEX(Subject!$B:$I,MATCH($F7,Subject!$C:$C,0),5)))} | I7: {=IF($F7="","",HYPERLINK(INDEX(Subject!$B:$I,MATCH($F7,Subject!$C:$C,0),6)))} | J7: {=IF($F7="","",HYPERLINK(INDEX(Subject!$B:$I,MATCH($F7,Subject!$C:$C,0),7)))} | K7: {=IF($F7="","",HYPERLINK(INDEX(Subject!$B:$I,MATCH($F7,Subject!$C:$C,0),8)))}
B8: =E1 -> 0.39583333 | C8: =E3 -> #N/A | D8: {=ifna(IF(INDEX(Subject!B:D,MATCH(F8,Subject!C:C,0),3)=0,"",(INDEX(Subject!B:D,MATCH(F8,Subject!C:C,0),3))),"")} | E8: =Now!C10 -> 0.39583333 | F8: =ifna(Now!D10,"") | G8: {=IF(F8="","",HYPERLINK(INDEX(Subject!B:E,MATCH(F8,Subject!C:C,0),4)))} | H8: {=IF($F8="","",HYPERLINK(INDEX(Subject!$B:$I,MATCH($F8,Subject!$C:$C,0),5)))} | I8: {=IF($F8="","",HYPERLINK(INDEX(Subject!$B:$I,MATCH($F8,Subject!$C:$C,0),6)))} | J8: {=IF($F8="","",HYPERLINK(INDEX(Subject!$B:$I,MATCH($F8,Subject!$C:$C,0),7)))} | K8: {=IF($F8="","",HYPERLINK(INDEX(Subject!$B:$I,MATCH($F8,Subject!$C:$C,0),8)))}
B9: =F1 -> 0.41666667 | C9: =F3 -> #N/A | D9: {=ifna(IF(INDEX(Subject!B:D,MATCH(F9,Subject!C:C,0),3)=0,"",(INDEX(Subject!B:D,MATCH(F9,Subject!C:C,0),3))),"")} | E9: =Now!C11 -> 0.41666667 | F9: =ifna(Now!D11,"") | G9: {=IF(F9="","",HYPERLINK(INDEX(Subject!B:E,MATCH(F9,Subject!C:C,0),4)))} | H9: {=IF($F9="","",HYPERLINK(INDEX(Subject!$B:$I,MATCH($F9,Subject!$C:$C,0),5)))} | I9: {=IF($F9="","",HYPERLINK(INDEX(Subject!$B:$I,MATCH($F9,Subject!$C:$C,0),6)))} | J9: {=IF($F9="","",HYPERLINK(INDEX(Subject!$B:$I,MATCH($F9,Subject!$C:$C,0),7)))} | K9: {=IF($F9="","",HYPERLINK(INDEX(Subject!$B:$I,MATCH($F9,Subject!$C:$C,0),8)))}
B10: =G1 -> 0.4375 | C10: =G3 -> #N/A | D10: {=ifna(IF(INDEX(Subject!B:D,MATCH(F10,Subject!C:C,0),3)=0,"",(INDEX(Subject!B:D,MATCH(F10,Subject!C:C,0),3))),"")} | E10: =Now!C12 -> 0.4375 | F10: =ifna(Now!D12,"") | G10: {=IF(F10="","",HYPERLINK(INDEX(Subject!B:E,MATCH(F10,Subject!C:C,0),4)))} | H10: {=IF($F10="","",HYPERLINK(INDEX(Subject!$B:$I,MATCH($F10,Subject!$C:$C,0),5)))} | I10: {=IF($F10="","",HYPERLINK(INDEX(Subject!$B:$I,MATCH($F10,Subject!$C:$C,0),6)))} | J10: {=IF($F10="","",HYPERLINK(INDEX(Subject!$B:$I,MATCH($F10,Subject!$C:$C,0),7)))} | K10: {=IF($F10="","",HYPERLINK(INDEX(Subject!$B:$I,MATCH($F10,Subject!$C:$C,0),8)))}
B11: =H1 -> 0.45833333 | C11: =H3 -> #N/A | D11: {=ifna(IF(INDEX(Subject!B:D,MATCH(F11,Subject!C:C,0),3)=0,"",(INDEX(Subject!B:D,MATCH(F11,Subject!C:C,0),3))),"")} | E11: =Now!C13 -> 0.45833333 | F11: =ifna(Now!D13,"") | G11: {=IF(F11="","",HYPERLINK(INDEX(Subject!B:E,MATCH(F11,Subject!C:C,0),4)))} | H11: {=IF($F11="","",HYPERLINK(INDEX(Subject!$B:$I,MATCH($F11,Subject!$C:$C,0),5)))} | I11: {=IF($F11="","",HYPERLINK(INDEX(Subject!$B:$I,MATCH($F11,Subject!$C:$C,0),6)))} | J11: {=IF($F11="","",HYPERLINK(INDEX(Subject!$B:$I,MATCH($F11,Subject!$C:$C,0),7)))} | K11: {=IF($F11="","",HYPERLINK(INDEX(Subject!$B:$I,MATCH($F11,Subject!$C:$C,0),8)))}
B12: =I1 -> 0.47916667 | C12: =I3 -> #N/A | D12: {=ifna(IF(INDEX(Subject!B:D,MATCH(F12,Subject!C:C,0),3)=0,"",(INDEX(Subject!B:D,MATCH(F12,Subject!C:C,0),3))),"")} | E12: =Now!C14 -> 0.47916667 | F12: =ifna(Now!D14,"") | G12: {=IF(F12="","",HYPERLINK(INDEX(Subject!B:E,MATCH(F12,Subject!C:C,0),4)))} | H12: {=IF($F12="","",HYPERLINK(INDEX(Subject!$B:$I,MATCH($F12,Subject!$C:$C,0),5)))} | I12: {=IF($F12="","",HYPERLINK(INDEX(Subject!$B:$I,MATCH($F12,Subject!$C:$C,0),6)))} | J12: {=IF($F12="","",HYPERLINK(INDEX(Subject!$B:$I,MATCH($F12,Subject!$C:$C,0),7)))} | K12: {=IF($F12="","",HYPERLINK(INDEX(Subject!$B:$I,MATCH($F12,Subject!$C:$C,0),8)))}
B13: =J1 -> 0.5 | C13: =J3 -> #N/A | D13: {=ifna(IF(INDEX(Subject!B:D,MATCH(F13,Subject!C:C,0),3)=0,"",(INDEX(Subject!B:D,MATCH(F13,Subject!C:C,0),3))),"")} | E13: =Now!C15 -> 0.5 | F13: =ifna(Now!D15,"") | G13: {=IF(F13="","",HYPERLINK(INDEX(Subject!B:E,MATCH(F13,Subject!C:C,0),4)))} | H13: {=IF($F13="","",HYPERLINK(INDEX(Subject!$B:$I,MATCH($F13,Subject!$C:$C,0),5)))} | I13: {=IF($F13="","",HYPERLINK(INDEX(Subject!$B:$I,MATCH($F13,Subject!$C:$C,0),6)))} | J13: {=IF($F13="","",HYPERLINK(INDEX(Subject!$B:$I,MATCH($F13,Subject!$C:$C,0),7)))} | K13: {=IF($F13="","",HYPERLINK(INDEX(Subject!$B:$I,MATCH($F13,Subject!$C:$C,0),8)))}
B14: =K1 -> 0.52083333 | C14: =K3 -> #N/A | D14: {=ifna(IF(INDEX(Subject!B:D,MATCH(F14,Subject!C:C,0),3)=0,"",(INDEX(Subject!B:D,MATCH(F14,Subject!C:C,0),3))),"")} | E14: =Now!C16 -> 0.52083333 | F14: =ifna(Now!D16,"") | G14: {=IF(F14="","",HYPERLINK(INDEX(Subject!B:E,MATCH(F14,Subject!C:C,0),4)))} | H14: {=IF($F14="","",HYPERLINK(INDEX(Subject!$B:$I,MATCH($F14,Subject!$C:$C,0),5)))} | I14: {=IF($F14="","",HYPERLINK(INDEX(Subject!$B:$I,MATCH($F14,Subject!$C:$C,0),6)))} | J14: {=IF($F14="","",HYPERLINK(INDEX(Subject!$B:$I,MATCH($F14,Subject!$C:$C,0),7)))} | K14: {=IF($F14="","",HYPERLINK(INDEX(Subject!$B:$I,MATCH($F14,Subject!$C:$C,0),8)))}
B15: =L1 -> 0.54166667 | C15: =L3 -> #N/A | D15: {=ifna(IF(INDEX(Subject!B:D,MATCH(F15,Subject!C:C,0),3)=0,"",(INDEX(Subject!B:D,MATCH(F15,Subject!C:C,0),3))),"")} | E15: =Now!C17 -> 0.54166667 | F15: =ifna(Now!D17,"") | G15: {=IF(F15="","",HYPERLINK(INDEX(Subject!B:E,MATCH(F15,Subject!C:C,0),4)))} | H15: {=IF($F15="","",HYPERLINK(INDEX(Subject!$B:$I,MATCH($F15,Subject!$C:$C,0),5)))} | I15: {=IF($F15="","",HYPERLINK(INDEX(Subject!$B:$I,MATCH($F15,Subject!$C:$C,0),6)))} | J15: {=IF($F15="","",HYPERLINK(INDEX(Subject!$B:$I,MATCH($F15,Subject!$C:$C,0),7)))} | K15: {=IF($F15="","",HYPERLINK(INDEX(Subject!$B:$I,MATCH($F15,Subject!$C:$C,0),8)))}
B16: =M1 -> 0.5625 | C16: =M3 -> #N/A | D16: {=ifna(IF(INDEX(Subject!B:D,MATCH(F16,Subject!C:C,0),3)=0,"",(INDEX(Subject!B:D,MATCH(F16,Subject!C:C,0),3))),"")} | E16: =Now!C18 -> 0.5625 | F16: =ifna(Now!D18,"") | G16: {=IF(F16="","",HYPERLINK(INDEX(Subject!B:E,MATCH(F16,Subject!C:C,0),4)))} | H16: {=IF($F16="","",HYPERLINK(INDEX(Subject!$B:$I,MATCH($F16,Subject!$C:$C,0),5)))} | I16: {=IF($F16="","",HYPERLINK(INDEX(Subject!$B:$I,MATCH($F16,Subject!$C:$C,0),6)))} | J16: {=IF($F16="","",HYPERLINK(INDEX(Subject!$B:$I,MATCH($F16,Subject!$C:$C,0),7)))} | K16: {=IF($F16="","",HYPERLINK(INDEX(Subject!$B:$I,MATCH($F16,Subject!$C:$C,0),8)))}
B17: =N1 -> 0.58333333 | C17: =N3 -> #N/A | D17: {=ifna(IF(INDEX(Subject!B:D,MATCH(F17,Subject!C:C,0),3)=0,"",(INDEX(Subject!B:D,MATCH(F17,Subject!C:C,0),3))),"")} | E17: =Now!C19 -> 0.58333333 | F17: =ifna(Now!D19,"") | G17: {=IF(F17="","",HYPERLINK(INDEX(Subject!B:E,MATCH(F17,Subject!C:C,0),4)))} | H17: {=IF($F17="","",HYPERLINK(INDEX(Subject!$B:$I,MATCH($F17,Subject!$C:$C,0),5)))} | I17: {=IF($F17="","",HYPERLINK(INDEX(Subject!$B:$I,MATCH($F17,Subject!$C:$C,0),6)))} | J17: {=IF($F17="","",HYPERLINK(INDEX(Subject!$B:$I,MATCH($F17,Subject!$C:$C,0),7)))} | K17: {=IF($F17="","",HYPERLINK(INDEX(Subject!$B:$I,MATCH($F17,Subject!$C:$C,0),8)))}
B18: =O1 -> 0.60416667 | C18: =O3 -> #N/A | D18: {=ifna(IF(INDEX(Subject!B:D,MATCH(F18,Subject!C:C,0),3)=0,"",(INDEX(Subject!B:D,MATCH(F18,Subject!C:C,0),3))),"")} | E18: =Now!C20 -> 0.60416667 | F18: =ifna(Now!D20,"") | G18: {=IF(F18="","",HYPERLINK(CELL("contents",INDEX(Subject!B:E,MATCH(F18,Subject!C:C,0),4))))} | H18: {=IF($F18="","",HYPERLINK(INDEX(Subject!$B:$I,MATCH($F18,Subject!$C:$C,0),5)))} | I18: {=IF($F18="","",HYPERLINK(INDEX(Subject!$B:$I,MATCH($F18,Subject!$C:$C,0),6)))} | J18: {=IF($F18="","",HYPERLINK(INDEX(Subject!$B:$I,MATCH($F18,Subject!$C:$C,0),7)))} | K18: {=IF($F18="","",HYPERLINK(INDEX(Subject!$B:$I,MATCH($F18,Subject!$C:$C,0),8)))}
B19: =P1 -> 0.625 | C19: =P3 -> #N/A | D19: {=ifna(IF(INDEX(Subject!B:D,MATCH(F19,Subject!C:C,0),3)=0,"",(INDEX(Subject!B:D,MATCH(F19,Subject!C:C,0),3))),"")} | E19: =Now!C21 -> 0.625 | F19: =ifna(Now!D21,"") | G19: {=ifna(IF(F19="","",HYPERLINK(INDEX(Subject!B:E,MATCH(F19,Subject!C:C,0),4))),"")} | H19: {=IF($F19="","",HYPERLINK(INDEX(Subject!$B:$I,MATCH($F19,Subject!$C:$C,0),5)))} | I19: {=IF($F19="","",HYPERLINK(INDEX(Subject!$B:$I,MATCH($F19,Subject!$C:$C,0),6)))} | J19: {=IF($F19="","",HYPERLINK(INDEX(Subject!$B:$I,MATCH($F19,Subject!$C:$C,0),7)))} | K19: {=IF($F19="","",HYPERLINK(INDEX(Subject!$B:$I,MATCH($F19,Subject!$C:$C,0),8)))}
B20: =Q1 -> 0.64583333 | C20: =Q3 -> #N/A | D20: {=ifna(IF(INDEX(Subject!B:D,MATCH(F20,Subject!C:C,0),3)=0,"",(INDEX(Subject!B:D,MATCH(F20,Subject!C:C,0),3))),"")} | E20: =Now!C22 -> 0.64583333 | F20: =ifna(Now!D22,"") | G20: {=ifna(IF(F20="","",HYPERLINK(INDEX(Subject!B:E,MATCH(F20,Subject!C:C,0),4))),"")} | H20: {=IF($F20="","",HYPERLINK(INDEX(Subject!$B:$I,MATCH($F20,Subject!$C:$C,0),5)))} | I20: {=IF($F20="","",HYPERLINK(INDEX(Subject!$B:$I,MATCH($F20,Subject!$C:$C,0),6)))} | J20: {=IF($F20="","",HYPERLINK(INDEX(Subject!$B:$I,MATCH($F20,Subject!$C:$C,0),7)))} | K20: {=IF($F20="","",HYPERLINK(INDEX(Subject!$B:$I,MATCH($F20,Subject!$C:$C,0),8)))}
B21: =R1 -> 0.66666667 | C21: =R3 -> #N/A | D21: {=ifna(IF(INDEX(Subject!B:D,MATCH(F21,Subject!C:C,0),3)=0,"",(INDEX(Subject!B:D,MATCH(F21,Subject!C:C,0),3))),"")} | E21: =Now!C23 -> 0.66666667 | F21: =ifna(Now!D23,"") | G21: {=IF(F21="","",HYPERLINK(INDEX(Subject!B:E,MATCH(F21,Subject!C:C,0),4)))} | H21: {=IF($F21="","",HYPERLINK(INDEX(Subject!$B:$I,MATCH($F21,Subject!$C:$C,0),5)))} | I21: {=IF($F21="","",HYPERLINK(INDEX(Subject!$B:$I,MATCH($F21,Subject!$C:$C,0),6)))} | J21: {=IF($F21="","",HYPERLINK(INDEX(Subject!$B:$I,MATCH($F21,Subject!$C:$C,0),7)))} | K21: {=IF($F21="","",HYPERLINK(INDEX(Subject!$B:$I,MATCH($F21,Subject!$C:$C,0),8)))}
B22: =S1 -> 0.6875 | C22: =S3 -> #N/A | D22: {=ifna(IF(INDEX(Subject!B:D,MATCH(F22,Subject!C:C,0),3)=0,"",(INDEX(Subject!B:D,MATCH(F22,Subject!C:C,0),3))),"")} | E22: =Now!C24 -> 0.6875 | F22: =ifna(Now!D24,"") | G22: {=IF(F22="","",HYPERLINK(INDEX(Subject!B:E,MATCH(F22,Subject!C:C,0),4)))} | H22: {=IF($F22="","",HYPERLINK(INDEX(Subject!$B:$I,MATCH($F22,Subject!$C:$C,0),5)))} | I22: {=IF($F22="","",HYPERLINK(INDEX(Subject!$B:$I,MATCH($F22,Subject!$C:$C,0),6)))} | J22: {=IF($F22="","",HYPERLINK(INDEX(Subject!$B:$I,MATCH($F22,Subject!$C:$C,0),7)))} | K22: {=IF($F22="","",HYPERLINK(INDEX(Subject!$B:$I,MATCH($F22,Subject!$C:$C,0),8)))}
B23: =T1 -> 0.70833333 | C23: =T3 -> #N/A | D23: {=ifna(IF(INDEX(Subject!B:D,MATCH(F23,Subject!C:C,0),3)=0,"",(INDEX(Subject!B:D,MATCH(F23,Subject!C:C,0),3))),"")} | E23: =Now!C25 -> 0.70833333 | F23: =ifna(Now!D25,"") | G23: {=IF(F23="","",HYPERLINK(INDEX(Subject!B:E,MATCH(F23,Subject!C:C,0),4)))} | H23: {=IF($F23="","",HYPERLINK(INDEX(Subject!$B:$I,MATCH($F23,Subject!$C:$C,0),5)))} | I23: {=IF($F23="","",HYPERLINK(INDEX(Subject!$B:$I,MATCH($F23,Subject!$C:$C,0),6)))} | J23: {=IF($F23="","",HYPERLINK(INDEX(Subject!$B:$I,MATCH($F23,Subject!$C:$C,0),7)))} | K23: {=IF($F23="","",HYPERLINK(INDEX(Subject!$B:$I,MATCH($F23,Subject!$C:$C,0),8)))}
B24: =U1 -> 0.72916667 | C24: =U3 -> #N/A | D24: {=ifna(IF(INDEX(Subject!B:D,MATCH(F24,Subject!C:C,0),3)=0,"",(INDEX(Subject!B:D,MATCH(F24,Subject!C:C,0),3))),"")} | E24: =Now!C26 -> 0.72916667 | F24: =ifna(Now!D26,"") | G24: {=IF(F24="","",HYPERLINK(INDEX(Subject!B:E,MATCH(F24,Subject!C:C,0),4)))} | H24: {=IF($F24="","",HYPERLINK(INDEX(Subject!$B:$I,MATCH($F24,Subject!$C:$C,0),5)))} | I24: {=IF($F24="","",HYPERLINK(INDEX(Subject!$B:$I,MATCH($F24,Subject!$C:$C,0),6)))} | J24: {=IF($F24="","",HYPERLINK(INDEX(Subject!$B:$I,MATCH($F24,Subject!$C:$C,0),7)))} | K24: {=IF($F24="","",HYPERLINK(INDEX(Subject!$B:$I,MATCH($F24,Subject!$C:$C,0),8)))}
B25: =V1 -> 0.75 | C25: =V3 -> #N/A | D25: {=ifna(IF(INDEX(Subject!B:D,MATCH(F25,Subject!C:C,0),3)=0,"",(INDEX(Subject!B:D,MATCH(F25,Subject!C:C,0),3))),"")} | E25: =Now!C27 -> 0.75 | F25: =ifna(Now!D27,"") | G25: {=IF(F25="","",HYPERLINK(INDEX(Subject!B:E,MATCH(F25,Subject!C:C,0),4)))} | H25: {=IF($F25="","",HYPERLINK(INDEX(Subject!$B:$I,MATCH($F25,Subject!$C:$C,0),5)))} | I25: {=IF($F25="","",HYPERLINK(INDEX(Subject!$B:$I,MATCH($F25,Subject!$C:$C,0),6)))} | J25: {=IF($F25="","",HYPERLINK(INDEX(Subject!$B:$I,MATCH($F25,Subject!$C:$C,0),7)))} | K25: {=IF($F25="","",HYPERLINK(INDEX(Subject!$B:$I,MATCH($F25,Subject!$C:$C,0),8)))}
B26: =W1 -> 0.77083333 | C26: =W3 -> #N/A | D26: {=ifna(IF(INDEX(Subject!B:D,MATCH(F26,Subject!C:C,0),3)=0,"",(INDEX(Subject!B:D,MATCH(F26,Subject!C:C,0),3))),"")} | E26: =Now!C28 -> 0.77083333 | F26: =ifna(Now!D28,"") | G26: {=IF(F26="","",HYPERLINK(INDEX(Subject!B:E,MATCH(F26,Subject!C:C,0),4)))} | H26: {=IF($F26="","",HYPERLINK(INDEX(Subject!$B:$I,MATCH($F26,Subject!$C:$C,0),5)))} | I26: {=IF($F26="","",HYPERLINK(INDEX(Subject!$B:$I,MATCH($F26,Subject!$C:$C,0),6)))} | J26: {=IF($F26="","",HYPERLINK(INDEX(Subject!$B:$I,MATCH($F26,Subject!$C:$C,0),7)))} | K26: {=IF($F26="","",HYPERLINK(INDEX(Subject!$B:$I,MATCH($F26,Subject!$C:$C,0),8)))}
B27: =X1 -> 0.79166667 | C27: =X3 -> #N/A | D27: {=ifna(IF(INDEX(Subject!B:D,MATCH(F27,Subject!C:C,0),3)=0,"",(INDEX(Subject!B:D,MATCH(F27,Subject!C:C,0),3))),"")} | E27: =Now!C29 -> 0.79166667 | F27: =ifna(Now!D29,"") | G27: {=IF(F27="","",HYPERLINK(INDEX(Subject!B:E,MATCH(F27,Subject!C:C,0),4)))} | H27: {=IF($F27="","",HYPERLINK(INDEX(Subject!$B:$I,MATCH($F27,Subject!$C:$C,0),5)))} | I27: {=IF($F27="","",HYPERLINK(INDEX(Subject!$B:$I,MATCH($F27,Subject!$C:$C,0),6)))} | J27: {=IF($F27="","",HYPERLINK(INDEX(Subject!$B:$I,MATCH($F27,Subject!$C:$C,0),7)))} | K27: {=IF($F27="","",HYPERLINK(INDEX(Subject!$B:$I,MATCH($F27,Subject!$C:$C,0),8)))}
B28: =Y1 -> 0.8125 | C28: =Y3 -> #N/A | D28: {=ifna(IF(INDEX(Subject!B:D,MATCH(F28,Subject!C:C,0),3)=0,"",(INDEX(Subject!B:D,MATCH(F28,Subject!C:C,0),3))),"")} | E28: =Now!C30 -> 0.8125 | F28: =ifna(Now!D30,"") | G28: {=IF(F28="","",HYPERLINK(INDEX(Subject!B:E,MATCH(F28,Subject!C:C,0),4)))} | H28: {=IF($F28="","",HYPERLINK(INDEX(Subject!$B:$I,MATCH($F28,Subject!$C:$C,0),5)))} | I28: {=IF($F28="","",HYPERLINK(INDEX(Subject!$B:$I,MATCH($F28,Subject!$C:$C,0),6)))} | J28: {=IF($F28="","",HYPERLINK(INDEX(Subject!$B:$I,MATCH($F28,Subject!$C:$C,0),7)))} | K28: {=IF($F28="","",HYPERLINK(INDEX(Subject!$B:$I,MATCH($F28,Subject!$C:$C,0),8)))}
B29: =Z1 -> 0.83333333 | C29: =Z3 -> #N/A | D29: {=ifna(IF(INDEX(Subject!B:D,MATCH(F29,Subject!C:C,0),3)=0,"",(INDEX(Subject!B:D,MATCH(F29,Subject!C:C,0),3))),"")} | E29: =Now!C31 -> 0.83333333 | F29: =ifna(Now!D31,"") | G29: {=IF(F29="","",HYPERLINK(INDEX(Subject!B:E,MATCH(F29,Subject!C:C,0),4)))} | H29: {=IF($F29="","",HYPERLINK(INDEX(Subject!$B:$I,MATCH($F29,Subject!$C:$C,0),5)))} | I29: {=IF($F29="","",HYPERLINK(INDEX(Subject!$B:$I,MATCH($F29,Subject!$C:$C,0),6)))} | J29: {=IF($F29="","",HYPERLINK(INDEX(Subject!$B:$I,MATCH($F29,Subject!$C:$C,0),7)))} | K29: {=IF($F29="","",HYPERLINK(INDEX(Subject!$B:$I,MATCH($F29,Subject!$C:$C,0),8)))}
B30: =AA1 -> 0.85416667 | C30: =AA3 -> #N/A | D30: {=ifna(IF(INDEX(Subject!B:D,MATCH(F30,Subject!C:C,0),3)=0,"",(INDEX(Subject!B:D,MATCH(F30,Subject!C:C,0),3))),"")} | E30: =Now!C32 -> 0.85416667 | F30: =ifna(Now!D32,"") | G30: {=IF(F30="","",HYPERLINK(INDEX(Subject!B:E,MATCH(F30,Subject!C:C,0),4)))} | H30: {=IF($F30="","",HYPERLINK(INDEX(Subject!$B:$I,MATCH($F30,Subject!$C:$C,0),5)))} | I30: {=IF($F30="","",HYPERLINK(INDEX(Subject!$B:$I,MATCH($F30,Subject!$C:$C,0),6)))} | J30: {=IF($F30="","",HYPERLINK(INDEX(Subject!$B:$I,MATCH($F30,Subject!$C:$C,0),7)))} | K30: {=IF($F30="","",HYPERLINK(INDEX(Subject!$B:$I,MATCH($F30,Subject!$C:$C,0),8)))}
B31: =AB1 -> 0.875 | C31: =AB3 -> #N/A | D31: {=ifna(IF(INDEX(Subject!B:D,MATCH(F31,Subject!C:C,0),3)=0,"",(INDEX(Subject!B:D,MATCH(F31,Subject!C:C,0),3))),"")} | E31: =Now!C33 -> 0.875 | F31: =ifna(Now!D33,"") | G31: {=IF(F31="","",HYPERLINK(INDEX(Subject!B:E,MATCH(F31,Subject!C:C,0),4)))} | H31: {=IF($F31="","",HYPERLINK(INDEX(Subject!$B:$I,MATCH($F31,Subject!$C:$C,0),5)))} | I31: {=IF($F31="","",HYPERLINK(INDEX(Subject!$B:$I,MATCH($F31,Subject!$C:$C,0),6)))} | J31: {=IF($F31="","",HYPERLINK(INDEX(Subject!$B:$I,MATCH($F31,Subject!$C:$C,0),7)))} | K31: {=IF($F31="","",HYPERLINK(INDEX(Subject!$B:$I,MATCH($F31,Subject!$C:$C,0),8)))}
B32: =AC1 -> 0.89583333 | C32: =AC3 -> #N/A | D32: {=ifna(IF(INDEX(Subject!B:D,MATCH(F32,Subject!C:C,0),3)=0,"",(INDEX(Subject!B:D,MATCH(F32,Subject!C:C,0),3))),"")} | E32: =Now!C34 -> 0.89583333 | F32: =ifna(Now!D34,"") | G32: {=IF(F32="","",HYPERLINK(INDEX(Subject!B:E,MATCH(F32,Subject!C:C,0),4)))} | H32: {=IF($F32="","",HYPERLINK(INDEX(Subject!$B:$I,MATCH($F32,Subject!$C:$C,0),5)))} | I32: {=IF($F32="","",HYPERLINK(INDEX(Subject!$B:$I,MATCH($F32,Subject!$C:$C,0),6)))} | J32: {=IF($F32="","",HYPERLINK(INDEX(Subject!$B:$I,MATCH($F32,Subject!$C:$C,0),7)))} | K32: {=IF($F32="","",HYPERLINK(INDEX(Subject!$B:$I,MATCH($F32,Subject!$C:$C,0),8)))}
B33: =AD1 -> 0.91666667 | C33: =AD3 -> #N/A | D33: {=ifna(IF(INDEX(Subject!B:D,MATCH(F33,Subject!C:C,0),3)=0,"",(INDEX(Subject!B:D,MATCH(F33,Subject!C:C,0),3))),"")} | E33: =Now!C35 -> 0.91666667 | F33: =ifna(Now!D35,"") | G33: {=IF(F33="","",HYPERLINK(INDEX(Subject!B:E,MATCH(F33,Subject!C:C,0),4)))} | H33: {=IF($F33="","",HYPERLINK(INDEX(Subject!$B:$I,MATCH($F33,Subject!$C:$C,0),5)))} | I33: {=IF($F33="","",HYPERLINK(INDEX(Subject!$B:$I,MATCH($F33,Subject!$C:$C,0),6)))} | J33: {=IF($F33="","",HYPERLINK(INDEX(Subject!$B:$I,MATCH($F33,Subject!$C:$C,0),7)))} | K33: {=IF($F33="","",HYPERLINK(INDEX(Subject!$B:$I,MATCH($F33,Subject!$C:$C,0),8)))}
B34: =AE1 -> 0.9375 | C34: =AE3 -> #N/A | D34: {=ifna(IF(INDEX(Subject!B:D,MATCH(F34,Subject!C:C,0),3)=0,"",(INDEX(Subject!B:D,MATCH(F34,Subject!C:C,0),3))),"")} | E34: =Now!C36 -> 0.9375 | F34: =ifna(Now!D36,"") | G34: {=IF(F34="","",HYPERLINK(INDEX(Subject!B:E,MATCH(F34,Subject!C:C,0),4)))} | H34: {=IF($F34="","",HYPERLINK(INDEX(Subject!$B:$I,MATCH($F34,Subject!$C:$C,0),5)))} | I34: {=IF($F34="","",HYPERLINK(INDEX(Subject!$B:$I,MATCH($F34,Subject!$C:$C,0),6)))} | J34: {=IF($F34="","",HYPERLINK(INDEX(Subject!$B:$I,MATCH($F34,Subject!$C:$C,0),7)))} | K34: {=IF($F34="","",HYPERLINK(INDEX(Subject!$B:$I,MATCH($F34,Subject!$C:$C,0),8)))}
B35: =AF1 -> 0.95833333 | C35: =AF3 -> #N/A | D35: {=ifna(IF(INDEX(Subject!B:D,MATCH(F35,Subject!C:C,0),3)=0,"",(INDEX(Subject!B:D,MATCH(F35,Subject!C:C,0),3))),"")} | E35: =Now!C37 -> 0.95833333 | F35: =ifna(Now!D37,"") | G35: {=IF(F35="","",HYPERLINK(INDEX(Subject!B:E,MATCH(F35,Subject!C:C,0),4)))} | H35: {=IF($F35="","",HYPERLINK(INDEX(Subject!$B:$I,MATCH($F35,Subject!$C:$C,0),5)))} | I35: {=IF($F35="","",HYPERLINK(INDEX(Subject!$B:$I,MATCH($F35,Subject!$C:$C,0),6)))} | J35: {=IF($F35="","",HYPERLINK(INDEX(Subject!$B:$I,MATCH($F35,Subject!$C:$C,0),7)))} | K35: {=IF($F35="","",HYPERLINK(INDEX(Subject!$B:$I,MATCH($F35,Subject!$C:$C,0),8)))}
B36: =AG1 -> 0.97916667 | C36: =AG3 -> #N/A | D36: {=ifna(IF(INDEX(Subject!B:D,MATCH(F36,Subject!C:C,0),3)=0,"",(INDEX(Subject!B:D,MATCH(F36,Subject!C:C,0),3))),"")} | E36: =Now!C38 -> 0.97916667 | F36: =ifna(Now!D38,"") | G36: {=IF(F36="","",HYPERLINK(INDEX(Subject!B:E,MATCH(F36,Subject!C:C,0),4)))} | H36: {=IF($F36="","",HYPERLINK(INDEX(Subject!$B:$I,MATCH($F36,Subject!$C:$C,0),5)))} | I36: {=IF($F36="","",HYPERLINK(INDEX(Subject!$B:$I,MATCH($F36,Subject!$C:$C,0),6)))} | J36: {=IF($F36="","",HYPERLINK(INDEX(Subject!$B:$I,MATCH($F36,Subject!$C:$C,0),7)))} | K36: {=IF($F36="","",HYPERLINK(INDEX(Subject!$B:$I,MATCH($F36,Subject!$C:$C,0),8)))}
B37: =AH1 -> 1 | C37: =AH3 -> #N/A | D37: {=ifna(IF(INDEX(Subject!B:D,MATCH(F37,Subject!C:C,0),3)=0,"",(INDEX(Subject!B:D,MATCH(F37,Subject!C:C,0),3))),"")} | E37: =Now!C39 -> 1 | F37: =ifna(Now!D39,"") | G37: {=IF(F37="","",HYPERLINK(INDEX(Subject!B:E,MATCH(F37,Subject!C:C,0),4)))} | H37: {=IF($F37="","",HYPERLINK(INDEX(Subject!$B:$I,MATCH($F37,Subject!$C:$C,0),5)))} | I37: {=IF($F37="","",HYPERLINK(INDEX(Subject!$B:$I,MATCH($F37,Subject!$C:$C,0),6)))} | J37: {=IF($F37="","",HYPERLINK(INDEX(Subject!$B:$I,MATCH($F37,Subject!$C:$C,0),7)))} | K37: {=IF($F37="","",HYPERLINK(INDEX(Subject!$B:$I,MATCH($F37,Subject!$C:$C,0),8)))}
B38: =AI1 -> 1.0208333 | C38: =AI3 -> #N/A | D38: {=ifna(IF(INDEX(Subject!B:D,MATCH(F38,Subject!C:C,0),3)=0,"",(INDEX(Subject!B:D,MATCH(F38,Subject!C:C,0),3))),"")} | E38: =Now!C40 -> 1.0208333 | F38: =ifna(Now!D40,"") | G38: {=IF(F38="","",HYPERLINK(INDEX(Subject!B:E,MATCH(F38,Subject!C:C,0),4)))} | H38: {=IF($F38="","",HYPERLINK(INDEX(Subject!$B:$I,MATCH($F38,Subject!$C:$C,0),5)))} | I38: {=IF($F38="","",HYPERLINK(INDEX(Subject!$B:$I,MATCH($F38,Subject!$C:$C,0),6)))} | J38: {=IF($F38="","",HYPERLINK(INDEX(Subject!$B:$I,MATCH($F38,Subject!$C:$C,0),7)))} | K38: {=IF($F38="","",HYPERLINK(INDEX(Subject!$B:$I,MATCH($F38,Subject!$C:$C,0),8)))}
B39: =AJ1 -> 1.0416667 | C39: =AJ3 -> #N/A | D39: {=ifna(IF(INDEX(Subject!B:D,MATCH(F39,Subject!C:C,0),3)=0,"",(INDEX(Subject!B:D,MATCH(F39,Subject!C:C,0),3))),"")} | E39: =Now!C41 -> 1.0416667 | F39: =ifna(Now!D41,"") | G39: {=IF(F39="","",HYPERLINK(INDEX(Subject!B:E,MATCH(F39,Subject!C:C,0),4)))} | H39: {=IF($F39="","",HYPERLINK(INDEX(Subject!$B:$I,MATCH($F39,Subject!$C:$C,0),5)))} | I39: {=IF($F39="","",HYPERLINK(INDEX(Subject!$B:$I,MATCH($F39,Subject!$C:$C,0),6)))} | J39: {=IF($F39="","",HYPERLINK(INDEX(Subject!$B:$I,MATCH($F39,Subject!$C:$C,0),7)))} | K39: {=IF($F39="","",HYPERLINK(INDEX(Subject!$B:$I,MATCH($F39,Subject!$C:$C,0),8)))}
B40: =AK1 -> 1.0625 | C40: =AK3 -> #N/A | D40: {=ifna(IF(INDEX(Subject!B:D,MATCH(F40,Subject!C:C,0),3)=0,"",(INDEX(Subject!B:D,MATCH(F40,Subject!C:C,0),3))),"")} | E40: =Now!C42 -> 1.0625 | F40: =ifna(Now!D42,"") | G40: {=IF(F40="","",HYPERLINK(INDEX(Subject!B:E,MATCH(F40,Subject!C:C,0),4)))} | H40: {=IF($F40="","",HYPERLINK(INDEX(Subject!$B:$I,MATCH($F40,Subject!$C:$C,0),5)))} | I40: {=IF($F40="","",HYPERLINK(INDEX(Subject!$B:$I,MATCH($F40,Subject!$C:$C,0),6)))} | J40: {=IF($F40="","",HYPERLINK(INDEX(Subject!$B:$I,MATCH($F40,Subject!$C:$C,0),7)))} | K40: {=IF($F40="","",HYPERLINK(INDEX(Subject!$B:$I,MATCH($F40,Subject!$C:$C,0),8)))}
...

Sheet Subject
A1: =MAX(B:B) -> 1 | C1: List of Subjects | D1: Notes | E1: Source or instructions
A2: =C2&" "&E2 | B2: 1 | C2: =IF(Planner!A5<>"",Planner!A5,"")
B3: =IF(C3<>"",B2+1,"") | C3: =IF(Planner!A6<>"",Planner!A6,"")
B4: =IF(C4<>"",B3+1,"") | C4: =IF(Planner!A7<>"",Planner!A7,"")
B5: =IF(C5<>"",B4+1,"") | C5: =IF(Planner!A8<>"",Planner!A8,"")
B6: =IF(C6<>"",B5+1,"") | C6: =IF(Planner!A9<>"",Planner!A9,"")
B7: =IF(C7<>"",B6+1,"") | C7: =IF(Planner!A10<>"",Planner!A10,"")
B8: =IF(C8<>"",B7+1,"") | C8: =IF(Planner!A11<>"",Planner!A11,"")
B9: =IF(C9<>"",B8+1,"") | C9: =IF(Planner!A12<>"",Planner!A12,"")
B10: =IF(C10<>"",B9+1,"") | C10: =IF(Planner!A13<>"",Planner!A13,"")
B11: =IF(C11<>"",B10+1,"") | C11: =IF(Planner!A14<>"",Planner!A14,"")
B12: =IF(C12<>"",B11+1,"") | C12: =IF(Planner!A15<>"",Planner!A15,"")
B13: =IF(C13<>"",B12+1,"") | C13: =IF(Planner!A16<>"",Planner!A16,"")
B14: =IF(C14<>"",B13+1,"") | C14: =IF(Planner!A17<>"",Planner!A17,"")
... B100: =IF(C100<>"",B99+1,"") | C100: =IF(Planner!A103<>"",Planner!A103,"")

Sheet Schedule
A1: =NOW() -> 46204.554 | B1: =B2 -> 0.33333333 | C1: =C2 -> 0.35416667 | D1: =D2 -> 0.375 | E1: =E2 -> 0.39583333 | F1: =F2 -> 0.41666667 | G1: =G2 -> 0.4375 | H1: =H2 -> 0.45833333 | I1: =I2 -> 0.47916667 | ... AL1: =AL2 -> 1.0833333
B2: 0.33333333 | C2: 0.35416667 | D2: 0.375 | E2: 0.39583333 | F2: 0.41666667 | G2: 0.4375 | H2: 0.45833333 | I2: 0.47916667 | J2: 0.5 | K2: 0.52083333 | L2: 0.54166667 | M2: 0.5625 | N2: 0.58333333 | O2: 0.60416667 | P2: 0.625 | Q2: 0.64583333 | R2: 0.66666667 | S2: 0.6875 | T2: 0.70833333 | U2: 0.72916667 | V2: 0.75 | W2: 0.77083333 | X2: 0.79166667 | Y2: 0.8125 | Z2: 0.83333333 | AA2: 0.85416667 | AB2: 0.875 | AC2: 0.89583333 | AD2: 0.91666667 | AE2: 0.9375 | AF2: 0.95833333 | AG2: 0.97916667 | AH2: 1 | AI2: 1.0208333 | AJ2: 1.0416667 | AK2: 1.0625 | AL2: 1.0833333
A3: 45503 | U3: {=INDEX(Subject!$A:$I,MATCH(RANDBETWEEN(1,16),Subject!$B:$B,0),3)} -> #N/A | AM3: =$A3+B$1 -> 45503.333 | AN3: =$A3+C$1 -> 45503.354 | AO3: =$A3+D$1 -> 45503.375 | AP3: =$A3+E$1 -> 45503.396 | AQ3: =$A3+F$1 -> 45503.417 | AR3: =$A3+G$1 -> 45503.438 | AS3: =$A3+H$1 -> 45503.458 | AT3: =$A3+I$1 -> 45503.479 | ... BZ3: =$A3+AO$1 -> 45503
A4: 45504 | B4: {=IF(NOW()>AM4,"",IF(AND((WEEKDAY($A4)+$B$2)>1,((WEEKDAY($A4)+$T$2)<7)),"work",(INDEX(Subject!$A:$I,MATCH(RANDBETWEEN(1,20),Subject!$B:$B,0),3))))} | C4: {=IF(NOW()>AN4,"",IF(AND((WEEKDAY($A4)+$B$2)>1,((WEEKDAY($A4)+$T$2)<7)),"work",(INDEX(Subject!$A:$I,MATCH(RANDBETWEEN(1,(MAX(Subject!B:B))),Subject!$B:$B,0),3))))} | D4: {=IF(NOW()>AO4,"",IF(AND((WEEKDAY($A4)+$B$2)>1,((WEEKDAY($A4)+$T$2)<7)),"work",(INDEX(Subject!$A:$I,MATCH(RANDBETWEEN(1,(MAX(Subject!C:C))),Subject!$B:$B,0),3))))} | E4: {=IF(NOW()>AP4,"",IF(AND((WEEKDAY($A4)+$B$2)>1,((WEEKDAY($A4)+$T$2)<7)),"work",(INDEX(Subject!$A:$I,MATCH(RANDBETWEEN(1,(MAX(Subject!D:D))),Subject!$B:$B,0),3))))} | F4: {=IF(NOW()>AQ4,"",IF(AND((WEEKDAY($A4)+$B$2)>1,((WEEKDAY($A4)+$T$2)<7)),"work",(INDEX(Subject!$A:$I,MATCH(RANDBETWEEN(1,(MAX(Subject!E:E))),Subject!$B:$B,0),3))))} | G4: {=IF(NOW()>AR4,"",IF(AND((WEEKDAY($A4)+$B$2)>1,((WEEKDAY($A4)+$T$2)<7)),"work",(INDEX(Subject!$A:$I,MATCH(RANDBETWEEN(1,(MAX(Subject!F:F))),Subject!$B:$B,0),3))))} | H4: {=IF(NOW()>AS4,"",IF(AND((WEEKDAY($A4)+$B$2)>1,((WEEKDAY($A4)+$T$2)<7)),"work",(INDEX(Subject!$A:$I,MATCH(RANDBETWEEN(1,(MAX(Subject!G:G))),Subject!$B:$B,0),3))))} | I4: {=IF(NOW()>AT4,"",IF(AND((WEEKDAY($A4)+$B$2)>1,((WEEKDAY($A4)+$T$2)<7)),"work",(INDEX(Subject!$A:$I,MATCH(RANDBETWEEN(1,(MAX(Subject!H:H))),Subject!$B:$B,0),3))))} | J4: {=IF(NOW()>AU4,"",IF(AND((WEEKDAY($A4)+$B$2)>1,((WEEKDAY($A4)+$T$2)<7)),"work",(INDEX(Subject!$A:$I,MATCH(RANDBETWEEN(1,(MAX(Subject!I:I))),Subject!$B:$B,0),3))))} | K4: {=IF(NOW()>AV4,"",IF(AND((WEEKDAY($A4)+$B$2)>1,((WEEKDAY($A4)+$T$2)<7)),"work",(INDEX(Subject!$A:$I,MATCH(RANDBETWEEN(1,(MAX(Subject!J:J))),Subject!$B:$B,0),3))))} | L4: {=IF(NOW()>AW4,"",IF(AND((WEEKDAY($A4)+$B$2)>1,((WEEKDAY($A4)+$T$2)<7)),"work",(INDEX(Subject!$A:$I,MATCH(RANDBETWEEN(1,(MAX(Subject!K:K))),Subject!$B:$B,0),3))))} | M4: {=IF(NOW()>AX4,"",IF(AND((WEEKDAY($A4)+$B$2)>1,((WEEKDAY($A4)+$T$2)<7)),"work",(INDEX(Subject!$A:$I,MATCH(RANDBETWEEN(1,(MAX(Subject!L:L))),Subject!$B:$B,0),3))))} | N4: {=IF(NOW()>AY4,"",IF(AND((WEEKDAY($A4)+$B$2)>1,((WEEKDAY($A4)+$T$2)<7)),"work",(INDEX(Subject!$A:$I,MATCH(RANDBETWEEN(1,(MAX(Subject!M:M))),Subject!$B:$B,0),3))))} | O4: {=IF(NOW()>AZ4,"",IF(AND((WEEKDAY($A4)+$B$2)>1,((WEEKDAY($A4)+$T$2)<7)),"work",(INDEX(Subject!$A:$I,MATCH(RANDBETWEEN(1,(MAX(Subject!N:N))),Subject!$B:$B,0),3))))} | P4: {=IF(NOW()>BA4,"",IF(AND((WEEKDAY($A4)+$B$2)>1,((WEEKDAY($A4)+$T$2)<7)),"work",(INDEX(Subject!$A:$I,MATCH(RANDBETWEEN(1,(MAX(Subject!O:O))),Subject!$B:$B,0),3))))} | Q4: {=IF(NOW()>BB4,"",IF(AND((WEEKDAY($A4)+$B$2)>1,((WEEKDAY($A4)+$T$2)<7)),"work",(INDEX(Subject!$A:$I,MATCH(RANDBETWEEN(1,(MAX(Subject!P:P))),Subject!$B:$B,0),3))))} | R4: {=IF(NOW()>BC4,"",IF(AND((WEEKDAY($A4)+$B$2)>1,((WEEKDAY($A4)+$T$2)<7)),"work",(INDEX(Subject!$A:$I,MATCH(RANDBETWEEN(1,(MAX(Subject!Q:Q))),Subject!$B:$B,0),3))))} | S4: {=IF(NOW()>BD4,"",IF(AND((WEEKDAY($A4)+$B$2)>1,((WEEKDAY($A4)+$T$2)<7)),"work",(INDEX(Subject!$A:$I,MATCH(RANDBETWEEN(1,(MAX(Subject!R:R))),Subject!$B:$B,0),3))))} | T4: {=IF(NOW()>BE4,"",IF(AND((WEEKDAY($A4)+$B$2)>1,((WEEKDAY($A4)+$T$2)<7)),"work",(INDEX(Subject!$A:$I,MATCH(RANDBETWEEN(1,(MAX(Subject!S:S))),Subject!$B:$B,0),3))))} | U4: {=INDEX(Subject!$A:$I,MATCH(RANDBETWEEN(1,16),Subject!$B:$B,0),3)} -> #N/A | V4: {=INDEX(Subject!$A:$I,MATCH(RANDBETWEEN(1,16),Subject!$B:$B,0),3)} -> #N/A | W4: {=INDEX(Subject!$A:$I,MATCH(RANDBETWEEN(1,16),Subject!$B:$B,0),3)} -> #N/A | X4: {=INDEX(Subject!$A:$I,MATCH(RANDBETWEEN(1,16),Subject!$B:$B,0),3)} -> #N/A | Y4: {=INDEX(Subject!$A:$I,MATCH(RANDBETWEEN(1,16),Subject!$B:$B,0),3)} -> #N/A | Z4: {=INDEX(Subject!$A:$I,MATCH(RANDBETWEEN(1,16),Subject!$B:$B,0),3)} -> #N/A | AA4: {=INDEX(Subject!$A:$I,MATCH(RANDBETWEEN(1,16),Subject!$B:$B,0),3)} -> #N/A | AB4: {=INDEX(Subject!$A:$I,MATCH(RANDBETWEEN(1,16),Subject!$B:$B,0),3)} -> #N/A | ... AL4: {=INDEX(Subject!$A:$I,MATCH(RANDBETWEEN(1,16),Subject!$B:$B,0),3)} -> #N/A | AM4: =A4+B$1 -> 45504.333 | AN4: =$A4+C$1 -> 45504.354 | AO4: =$A4+D$1 -> 45504.375 | AP4: =$A4+E$1 -> 45504.396 | AQ4: =$A4+F$1 -> 45504.417 | AR4: =$A4+G$1 -> 45504.438 | AS4: =$A4+H$1 -> 45504.458 | AT4: =$A4+I$1 -> 45504.479 | AU4: =$A4+J$1 -> 45504.5 | ... BZ4: =$A4+AO$1 -> 45504
A5: 45505 | B5: {=IF(NOW()>AM5,"",IF(AND((WEEKDAY($A5)+$B$2)>1,((WEEKDAY($A5)+$T$2)<7)),"work",(INDEX(Subject!$A:$I,MATCH(RANDBETWEEN(1,(MAX(Subject!$B:$B))),Subject!$B:$B,0),3))))} | C5: {=IF(NOW()>AN5,"",IF(AND((WEEKDAY($A5)+$B$2)>1,((WEEKDAY($A5)+$T$2)<7)),"work",(INDEX(Subject!$A:$I,MATCH(RANDBETWEEN(1,(MAX(Subject!$B:$B))),Subject!$B:$B,0),3))))} | D5: {=IF(NOW()>AO5,"",IF(AND((WEEKDAY($A5)+$B$2)>1,((WEEKDAY($A5)+$T$2)<7)),"work",(INDEX(Subject!$A:$I,MATCH(RANDBETWEEN(1,(MAX(Subject!$B:$B))),Subject!$B:$B,0),3))))} | E5: {=IF(NOW()>AP5,"",IF(AND((WEEKDAY($A5)+$B$2)>1,((WEEKDAY($A5)+$T$2)<7)),"work",(INDEX(Subject!$A:$I,MATCH(RANDBETWEEN(1,(MAX(Subject!$B:$B))),Subject!$B:$B,0),3))))} | F5: {=IF(NOW()>AQ5,"",IF(AND((WEEKDAY($A5)+$B$2)>1,((WEEKDAY($A5)+$T$2)<7)),"work",(INDEX(Subject!$A:$I,MATCH(RANDBETWEEN(1,(MAX(Subject!$B:$B))),Subject!$B:$B,0),3))))} | G5: {=IF(NOW()>AR5,"",IF(AND((WEEKDAY($A5)+$B$2)>1,((WEEKDAY($A5)+$T$2)<7)),"work",(INDEX(Subject!$A:$I,MATCH(RANDBETWEEN(1,(MAX(Subject!$B:$B))),Subject!$B:$B,0),3))))} | H5: {=IF(NOW()>AS5,"",IF(AND((WEEKDAY($A5)+$B$2)>1,((WEEKDAY($A5)+$T$2)<7)),"work",(INDEX(Subject!$A:$I,MATCH(RANDBETWEEN(1,(MAX(Subject!$B:$B))),Subject!$B:$B,0),3))))} | I5: {=IF(NOW()>AT5,"",IF(AND((WEEKDAY($A5)+$B$2)>1,((WEEKDAY($A5)+$T$2)<7)),"work",(INDEX(Subject!$A:$I,MATCH(RANDBETWEEN(1,(MAX(Subject!$B:$B))),Subject!$B:$B,0),3))))} | ... T5: {=IF(NOW()>BE5,"",IF(AND((WEEKDAY($A5)+$B$2)>1,((WEEKDAY($A5)+$T$2)<7)),"work",(INDEX(Subject!$A:$I,MATCH(RANDBETWEEN(1,(MAX(Subject!$B:$B))),Subject!$B:$B,0),3))))} | U5: {=INDEX(Subject!$A:$I,MATCH(RANDBETWEEN(1,16),Subject!$B:$B,0),3)} | V5: {=INDEX(Subject!$A:$I,MATCH(RANDBETWEEN(1,16),Subject!$B:$B,0),3)} -> #N/A | W5: {=INDEX(Subject!$A:$I,MATCH(RANDBETWEEN(1,16),Subject!$B:$B,0),3)} | X5: {=INDEX(Subject!$A:$I,MATCH(RANDBETWEEN(1,16),Subject!$B:$B,0),3)} -> #N/A | Y5: {=INDEX(Subject!$A:$I,MATCH(RANDBETWEEN(1,16),Subject!$B:$B,0),3)} -> #N/A | Z5: {=INDEX(Subject!$A:$I,MATCH(RANDBETWEEN(1,16),Subject!$B:$B,0),3)} -> #N/A | AA5: {=INDEX(Subject!$A:$I,MATCH(RANDBETWEEN(1,16),Subject!$B:$B,0),3)} -> #N/A | AB5: {=INDEX(Subject!$A:$I,MATCH(RANDBETWEEN(1,16),Subject!$B:$B,0),3)} -> #N/A | ... AL5: {=INDEX(Subject!$A:$I,MATCH(RANDBETWEEN(1,16),Subject!$B:$B,0),3)} -> #N/A | AM5: =A5+B$1 -> 45505.333 | AN5: =$A5+C$1 -> 45505.354 | AO5: =$A5+D$1 -> 45505.375 | AP5: =$A5+E$1 -> 45505.396 | AQ5: =$A5+F$1 -> 45505.417 | AR5: =$A5+G$1 -> 45505.438 | AS5: =$A5+H$1 -> 45505.458 | AT5: =$A5+I$1 -> 45505.479 | AU5: =$A5+J$1 -> 45505.5 | ... BZ5: =$A5+AO$1 -> 45505
A6: 45506 | B6: {=IF(NOW()>AM6,"",IF(AND((WEEKDAY($A6)+$B$2)>1,((WEEKDAY($A6)+$T$2)<7)),"work",(INDEX(Subject!$A:$I,MATCH(RANDBETWEEN(1,(MAX(Subject!$B:$B))),Subject!$B:$B,0),3))))} | C6: {=IF(NOW()>AN6,"",IF(AND((WEEKDAY($A6)+$B$2)>1,((WEEKDAY($A6)+$T$2)<7)),"work",(INDEX(Subject!$A:$I,MATCH(RANDBETWEEN(1,(MAX(Subject!$B:$B))),Subject!$B:$B,0),3))))} | D6: {=IF(NOW()>AO6,"",IF(AND((WEEKDAY($A6)+$B$2)>1,((WEEKDAY($A6)+$T$2)<7)),"work",(INDEX(Subject!$A:$I,MATCH(RANDBETWEEN(1,(MAX(Subject!$B:$B))),Subject!$B:$B,0),3))))} | E6: {=IF(NOW()>AP6,"",IF(AND((WEEKDAY($A6)+$B$2)>1,((WEEKDAY($A6)+$T$2)<7)),"work",(INDEX(Subject!$A:$I,MATCH(RANDBETWEEN(1,(MAX(Subject!$B:$B))),Subject!$B:$B,0),3))))} | F6: {=IF(NOW()>AQ6,"",IF(AND((WEEKDAY($A6)+$B$2)>1,((WEEKDAY($A6)+$T$2)<7)),"work",(INDEX(Subject!$A:$I,MATCH(RANDBETWEEN(1,(MAX(Subject!$B:$B))),Subject!$B:$B,0),3))))} | G6: {=IF(NOW()>AR6,"",IF(AND((WEEKDAY($A6)+$B$2)>1,((WEEKDAY($A6)+$T$2)<7)),"work",(INDEX(Subject!$A:$I,MATCH(RANDBETWEEN(1,(MAX(Subject!$B:$B))),Subject!$B:$B,0),3))))} | H6: {=IF(NOW()>AS6,"",IF(AND((WEEKDAY($A6)+$B$2)>1,((WEEKDAY($A6)+$T$2)<7)),"work",(INDEX(Subject!$A:$I,MATCH(RANDBETWEEN(1,(MAX(Subject!$B:$B))),Subject!$B:$B,0),3))))} | I6: {=IF(NOW()>AT6,"",IF(AND((WEEKDAY($A6)+$B$2)>1,((WEEKDAY($A6)+$T$2)<7)),"work",(INDEX(Subject!$A:$I,MATCH(RANDBETWEEN(1,(MAX(Subject!$B:$B))),Subject!$B:$B,0),3))))} | ... T6: {=IF(NOW()>BE6,"",IF(AND((WEEKDAY($A6)+$B$2)>1,((WEEKDAY($A6)+$T$2)<7)),"work",(INDEX(Subject!$A:$I,MATCH(RANDBETWEEN(1,(MAX(Subject!$B:$B))),Subject!$B:$B,0),3))))} | U6: {=INDEX(Subject!$A:$I,MATCH(RANDBETWEEN(1,16),Subject!$B:$B,0),3)} -> #N/A | V6: {=INDEX(Subject!$A:$I,MATCH(RANDBETWEEN(1,16),Subject!$B:$B,0),3)} -> #N/A | W6: {=INDEX(Subject!$A:$I,MATCH(RANDBETWEEN(1,16),Subject!$B:$B,0),3)} -> #N/A | X6: {=INDEX(Subject!$A:$I,MATCH(RANDBETWEEN(1,16),Subject!$B:$B,0),3)} -> #N/A | Y6: {=INDEX(Subject!$A:$I,MATCH(RANDBETWEEN(1,16),Subject!$B:$B,0),3)} -> #N/A | Z6: {=INDEX(Subject!$A:$I,MATCH(RANDBETWEEN(1,16),Subject!$B:$B,0),3)} -> #N/A | AA6: {=INDEX(Subject!$A:$I,MATCH(RANDBETWEEN(1,16),Subject!$B:$B,0),3)} -> #N/A | AB6: {=INDEX(Subject!$A:$I,MATCH(RANDBETWEEN(1,16),Subject!$B:$B,0),3)} -> #N/A | ... AL6: {=INDEX(Subject!$A:$I,MATCH(RANDBETWEEN(1,16),Subject!$B:$B,0),3)} -> #N/A | AM6: =A6+B$1 -> 45506.333 | AN6: =$A6+C$1 -> 45506.354 | AO6: =$A6+D$1 -> 45506.375 | AP6: =$A6+E$1 -> 45506.396 | AQ6: =$A6+F$1 -> 45506.417 | AR6: =$A6+G$1 -> 45506.438 | AS6: =$A6+H$1 -> 45506.458 | AT6: =$A6+I$1 -> 45506.479 | AU6: =$A6+J$1 -> 45506.5 | ... BZ6: =$A6+AO$1 -> 45506
A7: 45507 | B7: {=IF(NOW()>AM7,"",IF(AND((WEEKDAY($A7)+$B$2)>1,((WEEKDAY($A7)+$T$2)<7)),"work",(INDEX(Subject!$A:$I,MATCH(RANDBETWEEN(1,(MAX(Subject!$B:$B))),Subject!$B:$B,0),3))))} | C7: {=IF(NOW()>AN7,"",IF(AND((WEEKDAY($A7)+$B$2)>1,((WEEKDAY($A7)+$T$2)<7)),"work",(INDEX(Subject!$A:$I,MATCH(RANDBETWEEN(1,(MAX(Subject!$B:$B))),Subject!$B:$B,0),3))))} | D7: {=IF(NOW()>AO7,"",IF(AND((WEEKDAY($A7)+$B$2)>1,((WEEKDAY($A7)+$T$2)<7)),"work",(INDEX(Subject!$A:$I,MATCH(RANDBETWEEN(1,(MAX(Subject!$B:$B))),Subject!$B:$B,0),3))))} | E7: {=IF(NOW()>AP7,"",IF(AND((WEEKDAY($A7)+$B$2)>1,((WEEKDAY($A7)+$T$2)<7)),"work",(INDEX(Subject!$A:$I,MATCH(RANDBETWEEN(1,(MAX(Subject!$B:$B))),Subject!$B:$B,0),3))))} | F7: {=IF(NOW()>AQ7,"",IF(AND((WEEKDAY($A7)+$B$2)>1,((WEEKDAY($A7)+$T$2)<7)),"work",(INDEX(Subject!$A:$I,MATCH(RANDBETWEEN(1,(MAX(Subject!$B:$B))),Subject!$B:$B,0),3))))} | G7: {=IF(NOW()>AR7,"",IF(AND((WEEKDAY($A7)+$B$2)>1,((WEEKDAY($A7)+$T$2)<7)),"work",(INDEX(Subject!$A:$I,MATCH(RANDBETWEEN(1,(MAX(Subject!$B:$B))),Subject!$B:$B,0),3))))} | H7: {=IF(NOW()>AS7,"",IF(AND((WEEKDAY($A7)+$B$2)>1,((WEEKDAY($A7)+$T$2)<7)),"work",(INDEX(Subject!$A:$I,MATCH(RANDBETWEEN(1,(MAX(Subject!$B:$B))),Subject!$B:$B,0),3))))} | I7: {=IF(NOW()>AT7,"",IF(AND((WEEKDAY($A7)+$B$2)>1,((WEEKDAY($A7)+$T$2)<7)),"work",(INDEX(Subject!$A:$I,MATCH(RANDBETWEEN(1,(MAX(Subject!$B:$B))),Subject!$B:$B,0),3))))} | ... T7: {=IF(NOW()>BE7,"",IF(AND((WEEKDAY($A7)+$B$2)>1,((WEEKDAY($A7)+$T$2)<7)),"work",(INDEX(Subject!$A:$I,MATCH(RANDBETWEEN(1,(MAX(Subject!$B:$B))),Subject!$B:$B,0),3))))} | U7: {=INDEX(Subject!$A:$I,MATCH(RANDBETWEEN(1,16),Subject!$B:$B,0),3)} -> #N/A | V7: {=INDEX(Subject!$A:$I,MATCH(RANDBETWEEN(1,16),Subject!$B:$B,0),3)} -> #N/A | W7: {=INDEX(Subject!$A:$I,MATCH(RANDBETWEEN(1,16),Subject!$B:$B,0),3)} -> #N/A | X7: {=INDEX(Subject!$A:$I,MATCH(RANDBETWEEN(1,16),Subject!$B:$B,0),3)} -> #N/A | Y7: {=INDEX(Subject!$A:$I,MATCH(RANDBETWEEN(1,16),Subject!$B:$B,0),3)} -> #N/A | Z7: {=INDEX(Subject!$A:$I,MATCH(RANDBETWEEN(1,16),Subject!$B:$B,0),3)} -> #N/A | AA7: {=INDEX(Subject!$A:$I,MATCH(RANDBETWEEN(1,16),Subject!$B:$B,0),3)} -> #N/A | AB7: {=INDEX(Subject!$A:$I,MATCH(RANDBETWEEN(1,16),Subject!$B:$B,0),3)} -> #N/A | ... AL7: {=INDEX(Subject!$A:$I,MATCH(RANDBETWEEN(1,16),Subject!$B:$B,0),3)} -> #N/A | AM7: =A7+B$1 -> 45507.333 | AN7: =$A7+C$1 -> 45507.354 | AO7: =$A7+D$1 -> 45507.375 | AP7: =$A7+E$1 -> 45507.396 | AQ7: =$A7+F$1 -> 45507.417 | AR7: =$A7+G$1 -> 45507.438 | AS7: =$A7+H$1 -> 45507.458 | AT7: =$A7+I$1 -> 45507.479 | AU7: =$A7+J$1 -> 45507.5 | ... BZ7: =$A7+AO$1 -> 45507
A8: 45508 | B8: {=IF(NOW()>AM8,"",IF(AND((WEEKDAY($A8)+$B$2)>1,((WEEKDAY($A8)+$T$2)<7),(WEEKDAY($A8)<>1)),"work",(INDEX(Subject!$A:$I,MATCH(RANDBETWEEN(1,(MAX(Subject!$B:$B))),Subject!$B:$B,0),3))))} | C8: {=IF(NOW()>AN8,"",IF(AND((WEEKDAY($A8)+$B$2)>1,((WEEKDAY($A8)+$T$2)<7),(WEEKDAY($A8)<>1)),"work",(INDEX(Subject!$A:$I,MATCH(RANDBETWEEN(1,(MAX(Subject!$B:$B))),Subject!$B:$B,0),3))))} | D8: {=IF(NOW()>AO8,"",IF(AND((WEEKDAY($A8)+$B$2)>1,((WEEKDAY($A8)+$T$2)<7),(WEEKDAY($A8)<>1)),"work",(INDEX(Subject!$A:$I,MATCH(RANDBETWEEN(1,(MAX(Subject!$B:$B))),Subject!$B:$B,0),3))))} | E8: {=IF(NOW()>AP8,"",IF(AND((WEEKDAY($A8)+$B$2)>1,((WEEKDAY($A8)+$T$2)<7),(WEEKDAY($A8)<>1)),"work",(INDEX(Subject!$A:$I,MATCH(RANDBETWEEN(1,(MAX(Subject!$B:$B))),Subject!$B:$B,0),3))))} | F8: {=IF(NOW()>AQ8,"",IF(AND((WEEKDAY($A8)+$B$2)>1,((WEEKDAY($A8)+$T$2)<7),(WEEKDAY($A8)<>1)),"work",(INDEX(Subject!$A:$I,MATCH(RANDBETWEEN(1,(MAX(Subject!$B:$B))),Subject!$B:$B,0),3))))} | G8: {=IF(NOW()>AR8,"",IF(AND((WEEKDAY($A8)+$B$2)>1,((WEEKDAY($A8)+$T$2)<7),(WEEKDAY($A8)<>1)),"work",(INDEX(Subject!$A:$I,MATCH(RANDBETWEEN(1,(MAX(Subject!$B:$B))),Subject!$B:$B,0),3))))} | H8: {=IF(NOW()>AS8,"",IF(AND((WEEKDAY($A8)+$B$2)>1,((WEEKDAY($A8)+$T$2)<7),(WEEKDAY($A8)<>1)),"work",(INDEX(Subject!$A:$I,MATCH(RANDBETWEEN(1,(MAX(Subject!$B:$B))),Subject!$B:$B,0),3))))} | I8: {=IF(NOW()>AT8,"",IF(AND((WEEKDAY($A8)+$B$2)>1,((WEEKDAY($A8)+$T$2)<7),(WEEKDAY($A8)<>1)),"work",(INDEX(Subject!$A:$I,MATCH(RANDBETWEEN(1,(MAX(Subject!$B:$B))),Subject!$B:$B,0),3))))} | ... T8: {=IF(NOW()>BE8,"",IF(AND((WEEKDAY($A8)+$B$2)>1,((WEEKDAY($A8)+$T$2)<7),(WEEKDAY($A8)<>1)),"work",(INDEX(Subject!$A:$I,MATCH(RANDBETWEEN(1,(MAX(Subject!$B:$B))),Subject!$B:$B,0),3))))} | U8: {=INDEX(Subject!$A:$I,MATCH(RANDBETWEEN(1,16),Subject!$B:$B,0),3)} -> #N/A | V8: {=INDEX(Subject!$A:$I,MATCH(RANDBETWEEN(1,16),Subject!$B:$B,0),3)} -> #N/A | W8: {=INDEX(Subject!$A:$I,MATCH(RANDBETWEEN(1,16),Subject!$B:$B,0),3)} -> #N/A | X8: {=INDEX(Subject!$A:$I,MATCH(RANDBETWEEN(1,16),Subject!$B:$B,0),3)} -> #N/A | Y8: {=INDEX(Subject!$A:$I,MATCH(RANDBETWEEN(1,16),Subject!$B:$B,0),3)} -> #N/A | Z8: {=INDEX(Subject!$A:$I,MATCH(RANDBETWEEN(1,16),Subject!$B:$B,0),3)} -> #N/A | AA8: {=INDEX(Subject!$A:$I,MATCH(RANDBETWEEN(1,16),Subject!$B:$B,0),3)} -> #N/A | AB8: {=INDEX(Subject!$A:$I,MATCH(RANDBETWEEN(1,16),Subject!$B:$B,0),3)} -> #N/A | ... AL8: {=INDEX(Subject!$A:$I,MATCH(RANDBETWEEN(1,16),Subject!$B:$B,0),3)} -> #N/A | AM8: =A8+B$1 -> 45508.333 | AN8: =$A8+C$1 -> 45508.354 | AO8: =$A8+D$1 -> 45508.375 | AP8: =$A8+E$1 -> 45508.396 | AQ8: =$A8+F$1 -> 45508.417 | AR8: =$A8+G$1 -> 45508.438 | AS8: =$A8+H$1 -> 45508.458 | AT8: =$A8+I$1 -> 45508.479 | AU8: =$A8+J$1 -> 45508.5 | ... BZ8: =$A8+AO$1 -> 45508
A9: 45509 | B9: {=IF(NOW()>AM9,"",IF(AND((WEEKDAY($A9)+$B$2)>1,((WEEKDAY($A9)+$T$2)<7),(WEEKDAY($A9)<>1)),"work",(INDEX(Subject!$A:$I,MATCH(RANDBETWEEN(1,(MAX(Subject!$B:$B))),Subject!$B:$B,0),3))))} | C9: {=IF(NOW()>AN9,"",IF(AND((WEEKDAY($A9)+$B$2)>1,((WEEKDAY($A9)+$T$2)<7),(WEEKDAY($A9)<>1)),"work",(INDEX(Subject!$A:$I,MATCH(RANDBETWEEN(1,(MAX(Subject!$B:$B))),Subject!$B:$B,0),3))))} | D9: {=IF(NOW()>AO9,"",IF(AND((WEEKDAY($A9)+$B$2)>1,((WEEKDAY($A9)+$T$2)<7),(WEEKDAY($A9)<>1)),"work",(INDEX(Subject!$A:$I,MATCH(RANDBETWEEN(1,(MAX(Subject!$B:$B))),Subject!$B:$B,0),3))))} | E9: {=IF(NOW()>AP9,"",IF(AND((WEEKDAY($A9)+$B$2)>1,((WEEKDAY($A9)+$T$2)<7),(WEEKDAY($A9)<>1)),"work",(INDEX(Subject!$A:$I,MATCH(RANDBETWEEN(1,(MAX(Subject!$B:$B))),Subject!$B:$B,0),3))))} | F9: {=IF(NOW()>AQ9,"",IF(AND((WEEKDAY($A9)+$B$2)>1,((WEEKDAY($A9)+$T$2)<7),(WEEKDAY($A9)<>1)),"work",(INDEX(Subject!$A:$I,MATCH(RANDBETWEEN(1,(MAX(Subject!$B:$B))),Subject!$B:$B,0),3))))} | G9: {=IF(NOW()>AR9,"",IF(AND((WEEKDAY($A9)+$B$2)>1,((WEEKDAY($A9)+$T$2)<7),(WEEKDAY($A9)<>1)),"work",(INDEX(Subject!$A:$I,MATCH(RANDBETWEEN(1,(MAX(Subject!$B:$B))),Subject!$B:$B,0),3))))} | H9: {=IF(NOW()>AS9,"",IF(AND((WEEKDAY($A9)+$B$2)>1,((WEEKDAY($A9)+$T$2)<7),(WEEKDAY($A9)<>1)),"work",(INDEX(Subject!$A:$I,MATCH(RANDBETWEEN(1,(MAX(Subject!$B:$B))),Subject!$B:$B,0),3))))} | I9: {=IF(NOW()>AT9,"",IF(AND((WEEKDAY($A9)+$B$2)>1,((WEEKDAY($A9)+$T$2)<7),(WEEKDAY($A9)<>1)),"work",(INDEX(Subject!$A:$I,MATCH(RANDBETWEEN(1,(MAX(Subject!$B:$B))),Subject!$B:$B,0),3))))} | ... T9: {=IF(NOW()>BE9,"",IF(AND((WEEKDAY($A9)+$B$2)>1,((WEEKDAY($A9)+$T$2)<7),(WEEKDAY($A9)<>1)),"work",(INDEX(Subject!$A:$I,MATCH(RANDBETWEEN(1,(MAX(Subject!$B:$B))),Subject!$B:$B,0),3))))} | U9: {=INDEX(Subject!$A:$I,MATCH(RANDBETWEEN(1,16),Subject!$B:$B,0),3)} -> #N/A | V9: {=INDEX(Subject!$A:$I,MATCH(RANDBETWEEN(1,16),Subject!$B:$B,0),3)} -> #N/A | W9: {=INDEX(Subject!$A:$I,MATCH(RANDBETWEEN(1,16),Subject!$B:$B,0),3)} -> #N/A | X9: {=INDEX(Subject!$A:$I,MATCH(RANDBETWEEN(1,16),Subject!$B:$B,0),3)} -> #N/A | Y9: {=INDEX(Subject!$A:$I,MATCH(RANDBETWEEN(1,16),Subject!$B:$B,0),3)} -> #N/A | Z9: {=INDEX(Subject!$A:$I,MATCH(RANDBETWEEN(1,16),Subject!$B:$B,0),3)} -> #N/A | AA9: {=INDEX(Subject!$A:$I,MATCH(RANDBETWEEN(1,16),Subject!$B:$B,0),3)} -> #N/A | AB9: {=INDEX(Subject!$A:$I,MATCH(RANDBETWEEN(1,16),Subject!$B:$B,0),3)} -> #N/A | ... AL9: {=INDEX(Subject!$A:$I,MATCH(RANDBETWEEN(1,16),Subject!$B:$B,0),3)} -> #N/A | AM9: =A9+B$1 -> 45509.333 | AN9: =$A9+C$1 -> 45509.354 | AO9: =$A9+D$1 -> 45509.375 | AP9: =$A9+E$1 -> 45509.396 | AQ9: =$A9+F$1 -> 45509.417 | AR9: =$A9+G$1 -> 45509.438 | AS9: =$A9+H$1 -> 45509.458 | AT9: =$A9+I$1 -> 45509.479 | AU9: =$A9+J$1 -> 45509.5 | ... BZ9: =$A9+AO$1 -> 45509
A10: 45510 | B10: {=IF(NOW()>AM10,"",IF(AND((WEEKDAY($A10)+$B$2)>1,((WEEKDAY($A10)+$T$2)<7),(WEEKDAY($A10)<>1)),"work",(INDEX(Subject!$A:$I,MATCH(RANDBETWEEN(1,(MAX(Subject!$B:$B))),Subject!$B:$B,0),3))))} | C10: {=IF(NOW()>AN10,"",IF(AND((WEEKDAY($A10)+$B$2)>1,((WEEKDAY($A10)+$T$2)<7),(WEEKDAY($A10)<>1)),"work",(INDEX(Subject!$A:$I,MATCH(RANDBETWEEN(1,(MAX(Subject!$B:$B))),Subject!$B:$B,0),3))))} | D10: {=IF(NOW()>AO10,"",IF(AND((WEEKDAY($A10)+$B$2)>1,((WEEKDAY($A10)+$T$2)<7),(WEEKDAY($A10)<>1)),"work",(INDEX(Subject!$A:$I,MATCH(RANDBETWEEN(1,(MAX(Subject!$B:$B))),Subject!$B:$B,0),3))))} | E10: {=IF(NOW()>AP10,"",IF(AND((WEEKDAY($A10)+$B$2)>1,((WEEKDAY($A10)+$T$2)<7),(WEEKDAY($A10)<>1)),"work",(INDEX(Subject!$A:$I,MATCH(RANDBETWEEN(1,(MAX(Subject!$B:$B))),Subject!$B:$B,0),3))))} | F10: {=IF(NOW()>AQ10,"",IF(AND((WEEKDAY($A10)+$B$2)>1,((WEEKDAY($A10)+$T$2)<7),(WEEKDAY($A10)<>1)),"work",(INDEX(Subject!$A:$I,MATCH(RANDBETWEEN(1,(MAX(Subject!$B:$B))),Subject!$B:$B,0),3))))} | G10: {=IF(NOW()>AR10,"",IF(AND((WEEKDAY($A10)+$B$2)>1,((WEEKDAY($A10)+$T$2)<7),(WEEKDAY($A10)<>1)),"work",(INDEX(Subject!$A:$I,MATCH(RANDBETWEEN(1,(MAX(Subject!$B:$B))),Subject!$B:$B,0),3))))} | H10: {=IF(NOW()>AS10,"",IF(AND((WEEKDAY($A10)+$B$2)>1,((WEEKDAY($A10)+$T$2)<7),(WEEKDAY($A10)<>1)),"work",(INDEX(Subject!$A:$I,MATCH(RANDBETWEEN(1,(MAX(Subject!$B:$B))),Subject!$B:$B,0),3))))} | I10: {=IF(NOW()>AT10,"",IF(AND((WEEKDAY($A10)+$B$2)>1,((WEEKDAY($A10)+$T$2)<7),(WEEKDAY($A10)<>1)),"work",(INDEX(Subject!$A:$I,MATCH(RANDBETWEEN(1,(MAX(Subject!$B:$B))),Subject!$B:$B,0),3))))} | ... T10: {=IF(NOW()>BE10,"",IF(AND((WEEKDAY($A10)+$B$2)>1,((WEEKDAY($A10)+$T$2)<7),(WEEKDAY($A10)<>1)),"work",(INDEX(Subject!$A:$I,MATCH(RANDBETWEEN(1,(MAX(Subject!$B:$B))),Subject!$B:$B,0),3))))} | U10: {=INDEX(Subject!$A:$I,MATCH(RANDBETWEEN(1,16),Subject!$B:$B,0),3)} -> #N/A | V10: {=INDEX(Subject!$A:$I,MATCH(RANDBETWEEN(1,16),Subject!$B:$B,0),3)} -> #N/A | W10: {=INDEX(Subject!$A:$I,MATCH(RANDBETWEEN(1,16),Subject!$B:$B,0),3)} -> #N/A | X10: {=INDEX(Subject!$A:$I,MATCH(RANDBETWEEN(1,16),Subject!$B:$B,0),3)} -> #N/A | Y10: {=INDEX(Subject!$A:$I,MATCH(RANDBETWEEN(1,16),Subject!$B:$B,0),3)} -> #N/A | Z10: {=INDEX(Subject!$A:$I,MATCH(RANDBETWEEN(1,16),Subject!$B:$B,0),3)} -> #N/A | AA10: {=INDEX(Subject!$A:$I,MATCH(RANDBETWEEN(1,16),Subject!$B:$B,0),3)} -> #N/A | AB10: {=INDEX(Subject!$A:$I,MATCH(RANDBETWEEN(1,16),Subject!$B:$B,0),3)} -> #N/A | ... AL10: {=INDEX(Subject!$A:$I,MATCH(RANDBETWEEN(1,16),Subject!$B:$B,0),3)} -> #N/A | AM10: =A10+B$1 -> 45510.333 | AN10: =$A10+C$1 -> 45510.354 | AO10: =$A10+D$1 -> 45510.375 | AP10: =$A10+E$1 -> 45510.396 | AQ10: =$A10+F$1 -> 45510.417 | AR10: =$A10+G$1 -> 45510.438 | AS10: =$A10+H$1 -> 45510.458 | AT10: =$A10+I$1 -> 45510.479 | AU10: =$A10+J$1 -> 45510.5 | ... BZ10: =$A10+AO$1 -> 45510
